<robot name="uwaba_prototype" version="1.0">

  <!-- Some colour to our lil prototype :3 -->
  <material name="wheels-grey">
    <color rgba="0.25 0.25 0.25 1.00000" />
  </material>

  <material name="lidar-darkgrey">
    <color rgba="0.5 0.5 0.5 1.00000" />
  </material>

  <material name="base-blue">
    <color rgba="0 0 0.75 1.00000" />
  </material>

  <material name="support-babyblue">
    <color rgba="0.0 0.0 0.25 1.00000" />
  </material>

  <material name="suspension-black">
    <color rgba="1.0 1.0 1.0 1.00000" />
  </material>


  <joint name="base_footprint_joint" type="fixed">
    <origin rpy="0.0000000000 0.0000000000 0.0000000000"
      xyz="0.0000000177 0.0000000048 0.0524450019" />
    <parent link="base_footprint" />
    <child link="base_link" />
  </joint>
  <joint name="left_bumped_thread_base_joint" type="fixed">
    <origin rpy="0.0000000000 0.0000000000 0.0000000000"
      xyz="-0.0000073090 0.0762520012 -0.0125610121" />
    <parent link="base_link" />
    <child link="Left_bumped_treads_link" />
  </joint>
  <joint name="left_sprocket_base_joint" type="continuous">
    <limit lower="0" upper="0" effort="0.0000000000" velocity="0.0000000000" />
    <origin rpy="0.0000000000 0.0000000000 0.0000000000"
      xyz="-0.1065520449 0.0762500119 0.0002469979" />
    <parent link="base_link" />
    <child link="Left_wheel_sprocket_link" />
    <axis xyz="0.0000000000 1.0000000000 0.0000000000" />
  </joint>
  <joint name="left_suspension.001_base_joint" type="revolute">
    <limit lower="-0.1745329946" upper="0.1745329946" effort="0.0000000000" velocity="0.0000000000" />
    <origin rpy="0.0000000000 0.0000000000 0.0000000000"
      xyz="0.0515604214 0.0552990314 -0.0151900463" />
    <parent link="base_link" />
    <child link="Left_small_wheels_frame.001_link" />
    <axis xyz="0.0000000000 1.0000000000 0.0000000000" />
  </joint>
  <joint name="left_suspension.002_base_joint" type="revolute">
    <limit lower="-0.1745329946" upper="0.1745329946" effort="0.0000000000" velocity="0.0000000000" />
    <origin rpy="0.0000000000 0.0000000000 0.0000000000"
      xyz="0.0197104206 0.0552989979 -0.0151902959" />
    <parent link="base_link" />
    <child link="Left_small_wheels_frame.002_link" />
    <axis xyz="0.0000000000 1.0000000000 0.0000000000" />
  </joint>
  <joint name="left_suspension.003_base_joint" type="revolute">
    <limit lower="-0.1745329946" upper="0.1745329946" effort="0.0000000000" velocity="0.0000000000" />
    <origin rpy="0.0000000000 0.0000000000 0.0000000000"
      xyz="-0.0153435795 0.0552989904 -0.0151902996" />
    <parent link="base_link" />
    <child link="Left_small_wheels_frame.003_link" />
    <axis xyz="0.0000000000 1.0000000000 0.0000000000" />
  </joint>
  <joint name="left_suspension.004_base_joint" type="revolute">
    <limit lower="-0.1745329946" upper="0.1745329946" effort="0.0000000000" velocity="0.0000000000" />
    <origin rpy="0.0000000000 0.0000000000 0.0000000000"
      xyz="-0.0490785828 0.0552990314 -0.0151903071" />
    <parent link="base_link" />
    <child link="Left_small_wheels_frame.004_link" />
    <axis xyz="0.0000000000 1.0000000000 0.0000000000" />
  </joint>
  <joint name="left_suspension_base_joint" type="revolute">
    <limit lower="-0.1745329946" upper="0.1745329946" effort="0.0000000000" velocity="0.0000000000" />
    <origin rpy="0.0000000000 0.0000000000 0.0000000000"
      xyz="0.0879334183 0.0552990426 -0.0151902996" />
    <parent link="base_link" />
    <child link="Left_small_wheels_frame_link" />
    <axis xyz="0.0000000000 1.0000000000 0.0000000000" />
  </joint>
  <joint name="left_wheel.001_suspension_joint" type="fixed">
    <origin rpy="-0.0000000000 0.0000000000 0.0000000000"
      xyz="-0.0191554390 0.0209509283 -0.0199896954" />
    <parent link="Left_small_wheels_frame.004_link" />
    <child link="Left_wheel.001_link" />
  </joint>
  <joint name="left_wheel.002_suspension_joint" type="fixed">
    <origin rpy="-0.0000000000 0.0000000000 0.0000000000"
      xyz="-0.0184964389 0.0209509470 -0.0199897066" />
    <parent link="Left_small_wheels_frame.003_link" />
    <child link="Left_wheel.002_link" />
  </joint>
  <joint name="left_wheel.003_suspension_joint" type="fixed">
    <origin rpy="-0.0000000000 0.0000000000 0.0000000000"
      xyz="-0.0197104495 0.0209509693 -0.0199897159" />
    <parent link="Left_small_wheels_frame.002_link" />
    <child link="Left_wheel.003_link" />
  </joint>
  <joint name="left_wheel.004_suspension_joint" type="fixed">
    <origin rpy="-0.0000000000 0.0000000000 0.0000000000"
      xyz="-0.0179914646 0.0209509209 -0.0199899562" />
    <parent link="Left_small_wheels_frame.001_link" />
    <child link="Left_wheel.004_link" />
  </joint>
  <joint name="left_wheel.005_suspension_joint" type="fixed">
    <origin rpy="-0.0000000000 0.0000000000 0.0000000000"
      xyz="-0.0192444250 0.0209509395 -0.0199897159" />
    <parent link="Left_small_wheels_frame_link" />
    <child link="Left_wheel.005_link" />
  </joint>
  <joint name="left_wheel.006_base_joint" type="fixed">
    <origin rpy="0.0000000000 0.0000000000 0.0000000000"
      xyz="0.1065519945 0.0762500119 0.0002470016" />
    <parent link="base_link" />
    <child link="Left_wheel.006_link" />
  </joint>
  <joint name="right_bumped_thread_base_joint" type="fixed">
    <origin rpy="0.0000000000 0.0000000000 0.0000000000"
      xyz="0.0000440089 -0.0765780109 -0.0125610270" />
    <parent link="base_link" />
    <child link="Right_bumped_treads_link" />
  </joint>
  <joint name="right_sprocket_base_joint" type="continuous">
    <limit lower="0" upper="0" effort="0.0000000000" velocity="0.0000000000" />
    <origin rpy="0.0000000000 0.0000000000 0.0000000000"
      xyz="-0.1065520300 -0.0762500215 0.0002470128" />
    <parent link="base_link" />
    <child link="Right_wheel_sprocket_link" />
    <axis xyz="0.0000000000 1.0000000000 0.0000000000" />
  </joint>
  <joint name="right_suspension.001_base_joint" type="revolute">
    <limit lower="-0.1745329946" upper="0.1745329946" effort="0.0000000000" velocity="0.0000000000" />
    <origin rpy="0.0000000000 0.0000000000 0.0000000000"
      xyz="0.0515604140 -0.0552989628 -0.0151902884" />
    <parent link="base_link" />
    <child link="Right_small_wheels_frame.001_link" />
    <axis xyz="0.0000000000 1.0000000000 0.0000000000" />
  </joint>
  <joint name="right_suspension.002_base_joint" type="revolute">
    <limit lower="-0.1745329946" upper="0.1745329946" effort="0.0000000000" velocity="0.0000000000" />
    <origin rpy="0.0000000000 0.0000000000 0.0000000000"
      xyz="0.0197104187 -0.0552990224 -0.0151902996" />
    <parent link="base_link" />
    <child link="Right_small_wheels_frame.002_link" />
    <axis xyz="0.0000000000 1.0000000000 0.0000000000" />
  </joint>
  <joint name="right_suspension.003_base_joint" type="revolute">
    <limit lower="-0.1745329946" upper="0.1745329946" effort="0.0000000000" velocity="0.0000000000" />
    <origin rpy="0.0000000000 0.0000000000 0.0000000000"
      xyz="-0.0153435786 -0.0552990075 -0.0151903033" />
    <parent link="base_link" />
    <child link="Right_small_wheels_frame.003_link" />
    <axis xyz="0.0000000000 1.0000000000 0.0000000000" />
  </joint>
  <joint name="right_suspension.004_base_joint" type="revolute">
    <limit lower="-0.1745329946" upper="0.1745329946" effort="0.0000000000" velocity="0.0000000000" />
    <origin rpy="0.0000000000 0.0000000000 0.0000000000"
      xyz="-0.0490785791 -0.0552989665 -0.0151903071" />
    <parent link="base_link" />
    <child link="Right_small_wheels_frame.004_link" />
    <axis xyz="0.0000000000 1.0000000000 0.0000000000" />
  </joint>
  <joint name="right_suspension_base_joint" type="revolute">
    <limit lower="-0.1745329946" upper="0.1745329946" effort="0.0000000000" velocity="0.0000000000" />
    <origin rpy="0.0000000000 0.0000000000 0.0000000000"
      xyz="0.0879334183 -0.0552989665 -0.0151903033" />
    <parent link="base_link" />
    <child link="Right_small_wheels_frame_link" />
    <axis xyz="0.0000000000 1.0000000000 0.0000000000" />
  </joint>
  <joint name="right_wheel.001_suspension_joint" type="fixed">
    <origin rpy="0.0000000000 0.0000000000 0.0000000000"
      xyz="-0.0191554353 -0.0209510326 -0.0199897029" />
    <parent link="Right_small_wheels_frame.004_link" />
    <child link="Right_wheel.001_link" />
  </joint>
  <joint name="right_wheel.002_suspension_joint" type="fixed">
    <origin rpy="0.0000000000 0.0000000000 0.0000000000"
      xyz="-0.0184964174 -0.0209510289 -0.0199897103" />
    <parent link="Right_small_wheels_frame.003_link" />
    <child link="Right_wheel.002_link" />
  </joint>
  <joint name="right_wheel.003_suspension_joint" type="fixed">
    <origin rpy="0.0000000000 0.0000000000 0.0000000000"
      xyz="-0.0197104261 -0.0209509619 -0.0199897196" />
    <parent link="Right_small_wheels_frame.002_link" />
    <child link="Right_wheel.003_link" />
  </joint>
  <joint name="right_wheel.004_suspension_joint" type="fixed">
    <origin rpy="0.0000000000 0.0000000000 0.0000000000"
      xyz="-0.0179914236 -0.0209510438 -0.0199897178" />
    <parent link="Right_small_wheels_frame.001_link" />
    <child link="Right_wheel.004_link" />
  </joint>
  <joint name="right_wheel.005_suspension_joint" type="fixed">
    <origin rpy="0.0000000000 0.0000000000 0.0000000000"
      xyz="-0.0192444548 -0.0209510252 -0.0199896898" />
    <parent link="Right_small_wheels_frame_link" />
    <child link="Right_wheel.005_link" />
  </joint>
  <joint name="right_wheel.006_base_joint" type="fixed">
    <origin rpy="0.0000000000 0.0000000000 0.0000000000"
      xyz="0.1065519945 -0.0762500066 0.0002470054" />
    <parent link="base_link" />
    <child link="Right_wheel.006_link" />
  </joint>
  <joint name="scan_base_joint" type="fixed">
    <origin rpy="0.0000000000 0.0000000000 0.0000000000"
      xyz="-0.0110695819 -0.0000000043 0.0737789795" />
    <parent link="base_link" />
    <child link="scan_link" />
  </joint>
  <joint name="support_base_joint" type="fixed">
    <origin rpy="0.0000000000 0.0000000000 0.0000000000"
      xyz="-0.0090935585 -0.0004338986 0.0344425142" />
    <parent link="base_link" />
    <child link="support_link" />
  </joint>

  <link name="Left_bumped_treads_link">
    <collision name="Left_bumped_treads_collision">
      <origin rpy="0.0000000000 0.0000000000 0.0000000000"
        xyz="0.0000002912 -0.0000000075 0.0000000112" />
      <geometry>
        <mesh filename="../meshes/dae/right.tracks.dae"
          scale="1.0000000000 1.0000000000 1.0000000000" />
      </geometry>
    </collision>
    <visual name="Left_bumped_treads">
      <origin rpy="0.0000000000 0.0000000000 0.0000000000"
        xyz="0.0000000000 -0.0000000075 0.0000000000" />
      <geometry>
        <mesh filename="../meshes/dae/right.tracks.dae"
          scale="1.0000000000 1.0000000000 1.0000000000" />
      </geometry>
    </visual>
  </link>
  <link name="Left_small_wheels_frame.001_link">
    <collision name="Left_small_wheels_frame.001_collision">
      <origin rpy="0.0000000000 -0.7853982406 0.0000000000"
        xyz="-0.0084856115 0.0000000000 -0.0084856041" />
      <geometry>
        <box size="0.0362100005 0.0048000002 0.0085000005" />
      </geometry>
    </collision>
    <inertial>
      <inertia ixx="0.0000005956" ixy="-0.0000000000" ixz="-0.0000005162" iyy="0.0000011528"
        iyz="-0.0000000000" izz="0.0000005956" />
      <origin rpy="0.0000000000 0.0000000000 0.0000000000"
        xyz="-0.0000000075 -0.0000000037 0.0000000000" />
      <mass value="0.0099999998" />
    </inertial>
    <visual name="Left_small_wheels_frame.001">
      <material name="suspension-black" />
      <origin rpy="0.0000000000 -0.7853982406 0.0000000000"
        xyz="-0.0000000075 -0.0000000037 0.0000000000" />
      <geometry>
        <box size="0.0362099968 0.0048000002 0.0084999995" />
      </geometry>
    </visual>
  </link>
  <link name="Left_small_wheels_frame.002_link">
    <collision name="Left_small_wheels_frame.002_collision">
      <origin rpy="-0.0000000000 -0.7853982406 0.0000000000"
        xyz="-0.0084856041 0.0000000000 -0.0084856078" />
      <geometry>
        <box size="0.0362099968 0.0048000016 0.0085000005" />
      </geometry>
    </collision>
    <inertial>
      <inertia ixx="0.0000005956" ixy="-0.0000000000" ixz="-0.0000005162" iyy="0.0000011528"
        iyz="-0.0000000000" izz="0.0000005956" />
      <origin rpy="0.0000000000 0.0000000000 0.0000000000"
        xyz="0.0000000000 0.0000000000 0.0000000000" />
      <mass value="0.0099999998" />
    </inertial>
    <visual name="Left_small_wheels_frame.002">
      <material name="suspension-black" />
      <origin rpy="-0.0000000000 -0.7853982406 0.0000000000"
        xyz="0.0000000000 0.0000000000 0.0000000000" />
      <geometry>
        <box size="0.0362099968 0.0048000021 0.0085000005" />
      </geometry>
    </visual>
  </link>
  <link name="Left_small_wheels_frame.003_link">
    <collision name="Left_small_wheels_frame.003_collision">
      <origin rpy="-0.0000000000 -0.7853982406 0.0000000000"
        xyz="-0.0084852800 0.0000000075 -0.0084852818" />
      <geometry>
        <box size="0.0362099968 0.0047999993 0.0085000005" />
      </geometry>
    </collision>
    <inertial>
      <inertia ixx="0.0000005956" ixy="-0.0000000000" ixz="-0.0000005162" iyy="0.0000011528"
        iyz="-0.0000000000" izz="0.0000005956" />
      <origin rpy="0.0000000000 0.0000000000 0.0000000000"
        xyz="0.0000000000 0.0000000000 0.0000000000" />
      <mass value="0.0099999998" />
    </inertial>
    <visual name="Left_small_wheels_frame.003">
      <material name="suspension-black" />
      <origin rpy="-0.0000000000 -0.7853982406 0.0000000000"
        xyz="0.0000000000 0.0000000000 0.0000000000" />
      <geometry>
        <box size="0.0362099931 0.0047999993 0.0084999995" />
      </geometry>
    </visual>
  </link>
  <link name="Left_small_wheels_frame.004_link">
    <collision name="Left_small_wheels_frame.004_collision">
      <origin rpy="-0.0000000000 -0.7853982406 -0.0000000000"
        xyz="-0.0084852464 0.0000000037 -0.0084852353" />
      <geometry>
        <box size="0.0362100005 0.0048000002 0.0085000005" />
      </geometry>
    </collision>
    <inertial>
      <inertia ixx="0.0000005956" ixy="0.0000000000" ixz="-0.0000005162" iyy="0.0000011528"
        iyz="0.0000000000" izz="0.0000005956" />
      <origin rpy="0.0000000000 0.0000000000 0.0000000000"
        xyz="-0.0000000075 0.0000000075 0.0000000037" />
      <mass value="0.0099999998" />
    </inertial>
    <visual name="Left_small_wheels_frame.004">
      <material name="suspension-black" />
      <origin rpy="-0.0000000000 -0.7853982406 -0.0000000000"
        xyz="-0.0000000075 0.0000000075 0.0000000037" />
      <geometry>
        <box size="0.0362100005 0.0048000002 0.0085000005" />
      </geometry>
    </visual>
  </link>
  <link name="Left_small_wheels_frame_link">
    <collision name="Left_small_wheels_frame_collision">
      <origin rpy="0.0000000000 -0.7853982406 0.0000000000"
        xyz="-0.0084855407 0.0000000000 -0.0084855407" />
      <geometry>
        <box size="0.0362100005 0.0048000012 0.0085000005" />
      </geometry>
    </collision>
    <inertial>
      <inertia ixx="0.0000005956" ixy="-0.0000000000" ixz="-0.0000005162" iyy="0.0000011528"
        iyz="-0.0000000000" izz="0.0000005956" />
      <origin rpy="0.0000000000 0.0000000000 0.0000000000"
        xyz="0.0000000000 0.0000000000 0.0000000000" />
      <mass value="0.0099999998" />
    </inertial>
    <visual name="Left_small_wheels_frame">
      <material name="suspension-black" />
      <origin rpy="0.0000000000 -0.7853982406 0.0000000000"
        xyz="0.0000000000 0.0000000000 0.0000000000" />
      <geometry>
        <box size="0.0362100005 0.0048000012 0.0085000005" />
      </geometry>
    </visual>
  </link>
  <link name="Left_wheel.001_link">
    <collision name="Left_wheel.001_collision">
      <origin rpy="1.5707962513 0.0000000000 0.0000000000"
        xyz="0.0000000075 0.0000000000 -0.0000000037" />
      <geometry>
        <cylinder radius="0.0149999997" length="0.0219299998" />
      </geometry>
    </collision>
    <inertial>
      <inertia ixx="0.0000048164" ixy="-0.0000000000" ixz="0.0000000000" iyy="0.0000056250"
        iyz="-0.0000000000" izz="0.0000048164" />
      <origin rpy="0.0000000000 0.0000000000 0.0000000000"
        xyz="0.0000000075 0.0000000000 -0.0000000056" />
      <mass value="0.0500000007" />
    </inertial>
    <visual name="Left_wheel.001">
      <material name="wheels-grey" />
      <origin rpy="1.5707962513 0.0000000000 0.0000000000"
        xyz="0.0000000075 0.0000000000 -0.0000000056" />
      <geometry>
        <cylinder radius="0.0149999978" length="0.0219299998" />
      </geometry>
    </visual>
  </link>
  <link name="Left_wheel.002_link">
    <collision name="Left_wheel.002_collision">
      <origin rpy="1.5707962513 0.0000000000 0.0000000000"
        xyz="0.0000000000 0.0000000149 0.0000000019" />
      <geometry>
        <cylinder radius="0.0149999969" length="0.0219299998" />
      </geometry>
    </collision>
    <inertial>
      <inertia ixx="0.0000048164" ixy="-0.0000000000" ixz="0.0000000000" iyy="0.0000056250"
        iyz="-0.0000000000" izz="0.0000048164" />
      <origin rpy="0.0000000000 0.0000000000 0.0000000000"
        xyz="0.0000000000 0.0000000149 0.0000000019" />
      <mass value="0.0500000007" />
    </inertial>
    <visual name="Left_wheel.002">
      <material name="wheels-grey"/>
      <origin rpy="1.5707962513 0.0000000000 0.0000000000"
        xyz="0.0000000000 0.0000000149 0.0000000019" />
      <geometry>
        <cylinder radius="0.0149999950" length="0.0219299998" />
      </geometry>
    </visual>
  </link>
  <link name="Left_wheel.003_link">
    <collision name="Left_wheel.003_collision">
      <origin rpy="1.5707962513 0.0000000000 0.0000000000"
        xyz="0.0000000000 -0.0000000075 0.0000000019" />
      <geometry>
        <cylinder radius="0.0149999987" length="0.0219299998" />
      </geometry>
    </collision>
    <inertial>
      <inertia ixx="0.0000048164" ixy="-0.0000000000" ixz="-0.0000000000" iyy="0.0000056250"
        iyz="-0.0000000000" izz="0.0000048164" />
      <origin rpy="0.0000000000 0.0000000000 0.0000000000"
        xyz="0.0000000000 -0.0000000075 0.0000000019" />
      <mass value="0.0500000007" />
    </inertial>
    <visual name="Left_wheel.003">
      <material name="wheels-grey"/>
      <origin rpy="1.5707962513 0.0000000000 0.0000000000"
        xyz="0.0000000000 -0.0000000075 0.0000000019" />
      <geometry>
        <cylinder radius="0.0149999987" length="0.0219300017" />
      </geometry>
    </visual>
  </link>
  <link name="Left_wheel.004_link">
    <collision name="Left_wheel.004_collision">
      <origin rpy="1.5707962513 0.0000000000 0.0000000000"
        xyz="-0.0000000037 0.0000000075 0.0000000019" />
      <geometry>
        <cylinder radius="0.0150000006" length="0.0219299998" />
      </geometry>
    </collision>
    <inertial>
      <inertia ixx="0.0000048164" ixy="-0.0000000000" ixz="-0.0000000000" iyy="0.0000056250"
        iyz="-0.0000000000" izz="0.0000048164" />
      <origin rpy="0.0000000000 0.0000000000 0.0000000000"
        xyz="-0.0000000037 0.0000000075 0.0000000019" />
      <mass value="0.0500000007" />
    </inertial>
    <visual name="Left_wheel.004">
      <material name="wheels-grey"/>
      <origin rpy="1.5707962513 0.0000000000 0.0000000000"
        xyz="-0.0000000037 0.0000000075 0.0000000019" />
      <geometry>
        <cylinder radius="0.0149999987" length="0.0219299998" />
      </geometry>
    </visual>
  </link>
  <link name="Left_wheel.005_link">
    <collision name="Left_wheel.005_collision">
      <origin rpy="1.5707962513 0.0000000000 0.0000000000"
        xyz="0.0000000000 0.0000000075 0.0000000019" />
      <geometry>
        <cylinder radius="0.0150000015" length="0.0219299998" />
      </geometry>
    </collision>
    <inertial>
      <inertia ixx="0.0000048164" ixy="-0.0000000000" ixz="-0.0000000000" iyy="0.0000056250"
        iyz="-0.0000000000" izz="0.0000048164" />
      <origin rpy="0.0000000000 0.0000000000 0.0000000000"
        xyz="0.0000000000 0.0000000075 0.0000000019" />
      <mass value="0.0500000007" />
    </inertial>
    <visual name="Left_wheel.005">
      <material name="wheels-grey"/>
      <origin rpy="1.5707962513 0.0000000000 0.0000000000"
        xyz="0.0000000000 0.0000000075 0.0000000019" />
      <geometry>
        <cylinder radius="0.0150000025" length="0.0219300017" />
      </geometry>
    </visual>
  </link>
  <link name="Left_wheel.006_link">
    <collision name="Left_wheel.006_collision">
      <origin rpy="1.5707962513 0.0000000000 0.0000000000"
        xyz="-0.0000000075 0.0000000000 -0.0000000037" />
      <geometry>
        <cylinder radius="0.0161000043" length="0.0219299998" />
      </geometry>
    </collision>
    <inertial>
      <inertia ixx="0.0000078660" ixy="0.0000000000" ixz="0.0000000000" iyy="0.0000097204"
        iyz="-0.0000000000" izz="0.0000078660" />
      <origin rpy="0.0000000000 0.0000000000 0.0000000000"
        xyz="-0.0000000075 0.0000000000 -0.0000000037" />
      <mass value="0.0750000030" />
    </inertial>
    <visual name="Left_wheel.006">
      <material name="wheels-grey"/>
      <origin rpy="1.5707962513 0.0000000000 0.0000000000"
        xyz="-0.0000000075 0.0000000000 -0.0000000037" />
      <geometry>
        <cylinder radius="0.0161000006" length="0.0219299980" />
      </geometry>
    </visual>
  </link>
  <link name="Left_wheel_sprocket_link">
    <collision name="Left_wheel_sprocket_collision">
      <origin rpy="1.5707962513 0.0000000000 0.0000000000"
        xyz="0.0000000149 0.0000000000 -0.0000000075" />
      <geometry>
        <cylinder radius="0.0161000025" length="0.0219299998" />
      </geometry>
    </collision>
    <inertial>
      <inertia ixx="0.0000078660" ixy="0.0000000000" ixz="0.0000000000" iyy="0.0000097204"
        iyz="-0.0000000000" izz="0.0000078660" />
      <origin rpy="0.0000000000 0.0000000000 0.0000000000"
        xyz="0.0000000149 0.0000000000 -0.0000000075" />
      <mass value="0.0750000030" />
    </inertial>
    <visual name="Left_wheel_sprocket">
      <material name="wheels-grey"/>
      <origin rpy="1.5707962513 0.0000000000 0.0000000000"
        xyz="0.0000000149 0.0000000000 -0.0000000075" />
      <geometry>
        <cylinder radius="0.0161000006" length="0.0219299980" />
      </geometry>
    </visual>
  </link>
  <link name="Right_bumped_treads_link">
    <collision name="Right_bumped_treads_collision">
      <origin rpy="0.0000000000 0.0000000000 0.0000000000"
        xyz="-0.0000000266 0.0000000075 0.0000000261" />
      <geometry>
        <mesh filename="../meshes/dae/left.tracks.dae"
          scale="1.0000000000 1.0000000000 1.0000000000" />
      </geometry>
    </collision>
    <visual name="Right_bumped_treads">
      <origin rpy="0.0000000000 0.0000000000 0.0000000000"
        xyz="-0.0000000000 0.0000000000 0.0000000000" />
      <geometry>
        <mesh filename="../meshes/dae/left.tracks.dae"
          scale="1.0000000000 1.0000000000 1.0000000000" />
      </geometry>
    </visual>
  </link>
  <link name="Right_small_wheels_frame.001_link">
    <collision name="Right_small_wheels_frame.001_collision">
      <origin rpy="-0.0000000000 -0.7853982406 0.0000000000"
        xyz="-0.0084855929 -0.0000000075 -0.0084855966" />
      <geometry>
        <box size="0.0362099968 0.0048000072 0.0085000005" />
      </geometry>
    </collision>
    <inertial>
      <inertia ixx="0.0000005956" ixy="-0.0000000000" ixz="-0.0000005162" iyy="0.0000011528"
        iyz="-0.0000000000" izz="0.0000005956" />
      <origin rpy="0.0000000000 0.0000000000 0.0000000000"
        xyz="0.0000000000 -0.0000000037 0.0000000037" />
      <mass value="0.0099999998" />
    </inertial>
    <visual name="Right_small_wheels_frame.001">
      <material name="suspension-black" />
      <origin rpy="-0.0000000000 -0.7853982406 0.0000000000"
        xyz="0.0000000000 -0.0000000037 0.0000000037" />
      <geometry>
        <box size="0.0362099968 0.0048000072 0.0085000005" />
      </geometry>
    </visual>
  </link>
  <link name="Right_small_wheels_frame.002_link">
    <collision name="Right_small_wheels_frame.002_collision">
      <origin rpy="0.0000000000 -0.7853982406 0.0000000000"
        xyz="-0.0084856004 -0.0000000075 -0.0084856041" />
      <geometry>
        <box size="0.0362100005 0.0048000016 0.0085000005" />
      </geometry>
    </collision>
    <inertial>
      <inertia ixx="0.0000005956" ixy="-0.0000000000" ixz="-0.0000005162" iyy="0.0000011528"
        iyz="-0.0000000000" izz="0.0000005956" />
      <origin rpy="0.0000000000 0.0000000000 0.0000000000"
        xyz="0.0000000019 -0.0000000112 0.0000000000" />
      <mass value="0.0099999998" />
    </inertial>
    <visual name="Right_small_wheels_frame.002">
      <material name="suspension-black" />
      <origin rpy="0.0000000000 -0.7853982406 0.0000000000"
        xyz="0.0000000019 -0.0000000112 0.0000000000" />
      <geometry>
        <box size="0.0362100005 0.0048000021 0.0085000005" />
      </geometry>
    </visual>
  </link>
  <link name="Right_small_wheels_frame.003_link">
    <collision name="Right_small_wheels_frame.003_collision">
      <origin rpy="-0.0000000000 -0.7853982406 0.0000000000"
        xyz="-0.0084855026 0.0000000000 -0.0084855054" />
      <geometry>
        <box size="0.0362100005 0.0047999998 0.0085000005" />
      </geometry>
    </collision>
    <inertial>
      <inertia ixx="0.0000005956" ixy="-0.0000000000" ixz="-0.0000005162" iyy="0.0000011528"
        iyz="-0.0000000000" izz="0.0000005956" />
      <origin rpy="0.0000000000 0.0000000000 0.0000000000"
        xyz="0.0000000009 0.0000000037 -0.0000000037" />
      <mass value="0.0099999998" />
    </inertial>
    <visual name="Right_small_wheels_frame.003">
      <material name="suspension-black" />
      <origin rpy="-0.0000000000 -0.7853982406 0.0000000000"
        xyz="0.0000000009 0.0000000037 -0.0000000037" />
      <geometry>
        <box size="0.0362100005 0.0047999998 0.0085000005" />
      </geometry>
    </visual>
  </link>
  <link name="Right_small_wheels_frame.004_link">
    <collision name="Right_small_wheels_frame.004_collision">
      <origin rpy="-0.0000000000 -0.7853982406 -0.0000000000"
        xyz="-0.0084852390 0.0000000000 -0.0084852353" />
      <geometry>
        <box size="0.0362100005 0.0048000002 0.0085000005" />
      </geometry>
    </collision>
    <inertial>
      <inertia ixx="0.0000005956" ixy="0.0000000000" ixz="-0.0000005162" iyy="0.0000011528"
        iyz="0.0000000000" izz="0.0000005956" />
      <origin rpy="0.0000000000 0.0000000000 0.0000000000"
        xyz="-0.0000000037 0.0000000000 0.0000000000" />
      <mass value="0.0099999998" />
    </inertial>
    <visual name="Right_small_wheels_frame.004">
      <material name="suspension-black" />
      <origin rpy="-0.0000000000 -0.7853982406 -0.0000000000"
        xyz="-0.0000000037 0.0000000000 0.0000000000" />
      <geometry>
        <box size="0.0362100005 0.0048000002 0.0085000005" />
      </geometry>
    </visual>
  </link>
  <link name="Right_small_wheels_frame_link">
    <collision name="Right_small_wheels_frame_collision">
      <origin rpy="-0.0000000000 -0.7853982406 0.0000000000"
        xyz="-0.0084855556 0.0000000037 -0.0084855426" />
      <geometry>
        <box size="0.0362100005 0.0048000007 0.0085000005" />
      </geometry>
    </collision>
    <inertial>
      <inertia ixx="0.0000005956" ixy="-0.0000000000" ixz="-0.0000005162" iyy="0.0000011528"
        iyz="-0.0000000000" izz="0.0000005956" />
      <origin rpy="0.0000000000 0.0000000000 0.0000000000"
        xyz="-0.0000000075 0.0000000000 0.0000000000" />
      <mass value="0.0099999998" />
    </inertial>
    <visual name="Right_small_wheels_frame">
      <material name="suspension-black" />
      <origin rpy="-0.0000000000 -0.7853982406 0.0000000000"
        xyz="-0.0000000075 0.0000000000 0.0000000000" />
      <geometry>
        <box size="0.0362100005 0.0048000007 0.0085000005" />
      </geometry>
    </visual>
  </link>
  <link name="Right_wheel.001_link">
    <collision name="Right_wheel.001_collision">
      <origin rpy="-1.5707960129 -0.0000000000 0.0000000000"
        xyz="0.0000000000 0.0000000000 -0.0000000019" />
      <geometry>
        <cylinder radius="0.0149999997" length="0.0219299980" />
      </geometry>
    </collision>
    <inertial>
      <inertia ixx="0.0000048164" ixy="-0.0000000000" ixz="-0.0000000000" iyy="0.0000056250"
        iyz="0.0000000000" izz="0.0000048164" />
      <origin rpy="0.0000000000 0.0000000000 0.0000000000"
        xyz="0.0000000000 0.0000000000 -0.0000000019" />
      <mass value="0.0500000007" />
    </inertial>
    <visual name="Right_wheel.001">
      <material name="wheels-grey"/>
      <origin rpy="-1.5707960129 -0.0000000000 0.0000000000"
        xyz="0.0000000000 0.0000000000 -0.0000000019" />
      <geometry>
        <cylinder radius="0.0149999997" length="0.0219299980" />
      </geometry>
    </visual>
  </link>
  <link name="Right_wheel.002_link">
    <collision name="Right_wheel.002_collision">
      <origin rpy="-1.5707960129 0.0000000000 0.0000000000"
        xyz="0.0000000037 0.0000000000 -0.0000000019" />
      <geometry>
        <cylinder radius="0.0150000006" length="0.0219299980" />
      </geometry>
    </collision>
    <inertial>
      <inertia ixx="0.0000048164" ixy="-0.0000000000" ixz="-0.0000000000" iyy="0.0000056250"
        iyz="0.0000000000" izz="0.0000048164" />
      <origin rpy="0.0000000000 0.0000000000 0.0000000000"
        xyz="0.0000000037 0.0000000000 -0.0000000019" />
      <mass value="0.0500000007" />
    </inertial>
    <visual name="Right_wheel.002">
      <material name="wheels-grey"/>
      <origin rpy="-1.5707960129 0.0000000000 0.0000000000"
        xyz="0.0000000037 0.0000000000 -0.0000000019" />
      <geometry>
        <cylinder radius="0.0150000006" length="0.0219299980" />
      </geometry>
    </visual>
  </link>
  <link name="Right_wheel.003_link">
    <collision name="Right_wheel.003_collision">
      <origin rpy="-1.5707960129 -0.0000000000 0.0000000000"
        xyz="-0.0000000009 0.0000000000 0.0000000000" />
      <geometry>
        <cylinder radius="0.0149999997" length="0.0219299998" />
      </geometry>
    </collision>
    <inertial>
      <inertia ixx="0.0000048164" ixy="-0.0000000000" ixz="-0.0000000000" iyy="0.0000056250"
        iyz="0.0000000000" izz="0.0000048164" />
      <origin rpy="0.0000000000 0.0000000000 0.0000000000"
        xyz="-0.0000000000 0.0000000000 0.0000000000" />
      <mass value="0.0500000007" />
    </inertial>
    <visual name="Right_wheel.003">
      <material name="wheels-grey"/>
      <origin rpy="-1.5707960129 -0.0000000000 0.0000000000"
        xyz="-0.0000000000 0.0000000000 0.0000000000" />
      <geometry>
        <cylinder radius="0.0149999997" length="0.0219299998" />
      </geometry>
    </visual>
  </link>
  <link name="Right_wheel.004_link">
    <collision name="Right_wheel.004_collision">
      <origin rpy="-1.5707960129 -0.0000000000 0.0000000000"
        xyz="0.0000000000 0.0000000149 0.0000000000" />
      <geometry>
        <cylinder radius="0.0150000006" length="0.0219299980" />
      </geometry>
    </collision>
    <inertial>
      <inertia ixx="0.0000048164" ixy="0.0000000000" ixz="0.0000000000" iyy="0.0000056250"
        iyz="0.0000000000" izz="0.0000048164" />
      <origin rpy="0.0000000000 0.0000000000 0.0000000000"
        xyz="0.0000000000 0.0000000149 0.0000000000" />
      <mass value="0.0500000007" />
    </inertial>
    <visual name="Right_wheel.004">
      <material name="wheels-grey"/>
      <origin rpy="-1.5707960129 -0.0000000000 0.0000000000"
        xyz="0.0000000000 0.0000000149 0.0000000000" />
      <geometry>
        <cylinder radius="0.0150000006" length="0.0219299980" />
      </geometry>
    </visual>
  </link>
  <link name="Right_wheel.005_link">
    <collision name="Right_wheel.005_collision">
      <origin rpy="-1.5707960129 -0.0000000000 0.0000000000"
        xyz="-0.0000000149 0.0000000075 0.0000000000" />
      <geometry>
        <cylinder radius="0.0150000006" length="0.0219299980" />
      </geometry>
    </collision>
    <inertial>
      <inertia ixx="0.0000048164" ixy="-0.0000000000" ixz="-0.0000000000" iyy="0.0000056250"
        iyz="0.0000000000" izz="0.0000048164" />
      <origin rpy="0.0000000000 0.0000000000 0.0000000000"
        xyz="-0.0000000149 0.0000000075 0.0000000000" />
      <mass value="0.0500000007" />
    </inertial>
    <visual name="Right_wheel.005">
      <material name="wheels-grey"/>
      <origin rpy="-1.5707960129 -0.0000000000 0.0000000000"
        xyz="-0.0000000149 0.0000000075 0.0000000000" />
      <geometry>
        <cylinder radius="0.0150000006" length="0.0219299980" />
      </geometry>
    </visual>
  </link>
  <link name="Right_wheel.006_link">
    <collision name="Right_wheel.006_collision">
      <origin rpy="-1.5707956553 0.0000000000 0.0000000000"
        xyz="0.0000000000 0.0000000000 0.0000000000" />
      <geometry>
        <cylinder radius="0.0161000006" length="0.0219300017" />
      </geometry>
    </collision>
    <inertial>
      <inertia ixx="0.0000078660" ixy="0.0000000000" ixz="0.0000000000" iyy="0.0000097204"
        iyz="0.0000000000" izz="0.0000078660" />
      <origin rpy="0.0000000000 0.0000000000 0.0000000000"
        xyz="0.0000000000 0.0000000000 0.0000000000" />
      <mass value="0.0750000030" />
    </inertial>
    <visual name="Right_wheel.006">
      <material name="wheels-grey"/>
      <origin rpy="-1.5707956553 0.0000000000 0.0000000000"
        xyz="0.0000000000 0.0000000000 0.0000000000" />
      <geometry>
        <cylinder radius="0.0161000006" length="0.0219300017" />
      </geometry>
    </visual>
  </link>
  <link name="Right_wheel_sprocket_link">
    <collision name="Right_wheel_sprocket_collision">
      <origin rpy="-1.5707956553 0.0000000000 0.0000000000"
        xyz="0.0000000075 0.0000000075 0.0000000000" />
      <geometry>
        <cylinder radius="0.0161000006" length="0.0219300017" />
      </geometry>
    </collision>
    <inertial>
      <inertia ixx="0.0000078660" ixy="0.0000000000" ixz="0.0000000000" iyy="0.0000097204"
        iyz="0.0000000000" izz="0.0000078660" />
      <origin rpy="0.0000000000 0.0000000000 0.0000000000"
        xyz="0.0000000075 0.0000000075 0.0000000000" />
      <mass value="0.0750000030" />
    </inertial>
    <visual name="Right_wheel_sprocket">
      <material name="wheels-grey"/>
      <origin rpy="-1.5707956553 0.0000000000 0.0000000000"
        xyz="0.0000000075 0.0000000075 0.0000000000" />
      <geometry>
        <cylinder radius="0.0160999987" length="0.0219299998" />
      </geometry>
    </visual>
  </link>
  <link name="base_footprint" />
  <link name="base_link">
    <collision name="base_collision">
      <origin rpy="0.0000000000 0.0000000000 0.0000000000"
        xyz="0.0000000000 0.0000000000 0.0000000000" />
      <geometry>
        <box size="0.2480000407 0.1058000177 0.0387500003" />
      </geometry>
    </collision>
    <inertial>
      <inertia ixx="0.0010579339" ixy="0.0000000000" ixz="0.0000000000" iyy="0.0052504652"
        iyz="0.0000000000" izz="0.0060581387" />
      <origin rpy="0.0000000000 0.0000000000 0.0000000000"
        xyz="0.0000000000 0.0000000000 0.0000000000" />
      <mass value="1.0000000000" />
    </inertial>
    <visual name="base">
      <material name="base-blue"/>
      <origin rpy="0.0000000000 0.0000000000 0.0000000000"
        xyz="0.0000000000 0.0000000000 0.0000000000" />
      <geometry>
        <box size="0.2480000407 0.1058000177 0.0387500003" />
      </geometry>
    </visual>
  </link>
  <link name="scan_link">
    <collision name="scan_collision">
      <origin rpy="0.0000000000 0.0000000000 0.0000000000"
        xyz="0.0000000000 -0.0000000000 0.0000000000" />
      <geometry>
        <cylinder radius="0.0341599993" length="0.0183099993" />
      </geometry>
    </collision>
    <inertial>
      <inertia ixx="0.0000799161" ixy="0.0000000000" ixz="0.0000000000" iyy="0.0000799161"
        iyz="0.0000000000" izz="0.0001458632" />
      <origin rpy="0.0000000000 0.0000000000 0.0000000000"
        xyz="0.0000000000 -0.0000000000 0.0000000000" />
      <mass value="0.2500000000" />
    </inertial>
    <visual name="scan">
      <material name="lidar-darkgrey"/>
      <origin rpy="0.0000000000 0.0000000000 0.0000000000"
        xyz="0.0000000000 -0.0000000000 0.0000000000" />
      <geometry>
        <cylinder radius="0.0341599993" length="0.0183099993" />
      </geometry>
    </visual>
  </link>
  <link name="support_link">
    <collision name="support_collision">
      <origin rpy="0.0000000000 0.0000000000 0.0000000000"
        xyz="-0.0000004601 -0.0000001062 0.0000004768" />
      <geometry>
        <mesh filename="../meshes/dae/Cube.002.dae" scale="1.0000000000 1.0000000000 0.9999898672" />
      </geometry>
    </collision>
    <inertial>
      <inertia ixx="0.0001558814" ixy="0.0000000000" ixz="0.0000000000" iyy="0.0007847610"
        iyz="0.0000000000" izz="0.0009087205" />
      <origin rpy="0.0000000000 0.0000000000 0.0000000000"
        xyz="-0.0000000011 0.0000000000 -0.0000000175" />
      <mass value="0.1500000060" />
    </inertial>
    <visual name="support">
      <material name="support-babyblue"/>
      <origin rpy="0.0000000000 0.0000000000 0.0000000000"
        xyz="-0.0000000019 0.0000000000 -0.0000000075" />
      <geometry>
        <box size="0.2480000257 0.1058000028 0.0357334018" />
      </geometry>
    </visual>
  </link>
</robot>