<robot name="uWABA" version="1.0">

  <material name="grey">
    <color rgba="0.5 0.5 0.5 1" />
  </material>

  <material name="red">
    <color rgba="1 0 0 0.5" />
  </material>

  <material name="white">
    <color rgba="1 1 1 1" />
  </material>

  <material name="blue">
    <color rgba="0 0 0.5 1" />
  </material>

  <material name="black">
    <color rgba="0.25 0.25 0.25 1" />
  </material>

  <joint name="base_laser_joint" type="fixed">
    <origin rpy="0.0000000000 0.0000000000 0.0000000000" xyz="0.0865522291 -0.0000000015 0.0611436181"/>
    <parent link="base_link"/>
    <child link="laser_link"/>
  </joint>
  <joint name="base_left_small_suspesion.001_joint" type="revolute">
    <limit lower="-0.0872664973" upper="0.0872664973" effort="0.0000000000" velocity="0.0000000000"/>
    <origin rpy="0.0000000000 0.0000000000 0.0000000000" xyz="0.0426865297 0.0552990415 -0.0245030019"/>
    <parent link="base_link"/>
    <child link="Left_small_wheels_frame.001_link"/>
    <axis xyz="0.0000000000 1.0000000000 0.0000000000"/>
  </joint>
  <joint name="base_left_small_suspesion.002_joint" type="revolute">
    <limit lower="-0.0872664973" upper="0.0872664973" effort="0.0000000000" velocity="0.0000000000"/>
    <origin rpy="0.0000000000 0.0000000000 0.0000000000" xyz="0.0108365280 0.0552989968 -0.0245032571"/>
    <parent link="base_link"/>
    <child link="Left_small_wheels_frame.002_link"/>
    <axis xyz="0.0000000000 1.0000000000 0.0000000000"/>
  </joint>
  <joint name="base_left_small_suspesion.003_joint" type="revolute">
    <limit lower="-0.0872664973" upper="0.0872664973" effort="0.0000000000" velocity="0.0000000000"/>
    <origin rpy="0.0000000000 0.0000000000 0.0000000000" xyz="-0.0242170148 0.0552989968 -0.0245032609"/>
    <parent link="base_link"/>
    <child link="Left_small_wheels_frame.003_link"/>
    <axis xyz="0.0000000000 1.0000000000 0.0000000000"/>
  </joint>
  <joint name="base_left_small_suspesion.004_joint" type="revolute">
    <limit lower="-0.0872664973" upper="0.0872664973" effort="0.0000000000" velocity="0.0000000000"/>
    <origin rpy="0.0000000000 0.0000000000 0.0000000000" xyz="-0.0579519530 0.0552990266 -0.0245032683"/>
    <parent link="base_link"/>
    <child link="Left_small_wheels_frame.004_link"/>
    <axis xyz="0.0000000000 1.0000000000 0.0000000000"/>
  </joint>
  <joint name="base_left_small_suspesion_joint" type="revolute">
    <limit lower="-0.0872664973" upper="0.0872664973" effort="0.0000000000" velocity="0.0000000000"/>
    <origin rpy="0.0000000000 0.0000000000 0.0000000000" xyz="0.0790596123 0.0552990415 -0.0245032590"/>
    <parent link="base_link"/>
    <child link="Left_small_wheels_frame_link"/>
    <axis xyz="0.0000000000 1.0000000000 0.0000000000"/>
  </joint>
  <joint name="base_left_wheel.001_joint" type="fixed">
    <origin rpy="0.0000000000 0.0000000000 0.0000000000" xyz="-0.0102820545 0.0209509507 -0.0114647429"/>
    <parent link="Left_small_wheels_frame.004_link"/>
    <child link="Left_wheel.001_link"/>
  </joint>
  <joint name="base_left_wheel.002_joint" type="fixed">
    <origin rpy="0.0000000000 0.0000000000 0.0000000000" xyz="-0.0096230004 0.0209509805 -0.0114647467"/>
    <parent link="Left_small_wheels_frame.003_link"/>
    <child link="Left_wheel.002_link"/>
  </joint>
  <joint name="base_left_wheel.003_joint" type="fixed">
    <origin rpy="0.0000000000 0.0000000000 0.0000000000" xyz="-0.0108365483 0.0209509954 -0.0114647485"/>
    <parent link="Left_small_wheels_frame.002_link"/>
    <child link="Left_wheel.003_link"/>
  </joint>
  <joint name="base_left_wheel.004_joint" type="fixed">
    <origin rpy="0.0000000000 0.0000000000 0.0000000000" xyz="-0.0091175586 0.0209509358 -0.0114649981"/>
    <parent link="Left_small_wheels_frame.001_link"/>
    <child link="Left_wheel.004_link"/>
  </joint>
  <joint name="base_left_wheel.005_joint" type="fixed">
    <origin rpy="0.0000000000 0.0000000000 0.0000000000" xyz="-0.0103706270 0.0209509507 -0.0114647523"/>
    <parent link="Left_small_wheels_frame_link"/>
    <child link="Left_wheel.005_link"/>
  </joint>
  <joint name="base_left_wheel.006_joint" type="fixed">
    <origin rpy="0.0000000000 0.0000000000 0.0000000000" xyz="0.1065519790 0.0762500145 -0.0005410053"/>
    <parent link="base_link"/>
    <child link="Left_wheel.006_link"/>
  </joint>
  <joint name="base_left_wheel_sprocket_joint" type="fixed">
    <origin rpy="0.0000000000 0.0000000000 0.0000000000" xyz="-0.1065520157 0.0762499996 -0.0005410016"/>
    <parent link="base_link"/>
    <child link="Left_wheel_sprocket_link"/>
  </joint>
  <joint name="base_link_joint" type="fixed">
    <origin rpy="0.0000000000 0.0000000000 0.0000000000" xyz="0.0000000109 0.0000000022 0.0532330014"/>
    <parent link="base_footprint"/>
    <child link="base_link"/>
  </joint>
  <joint name="base_right_small_suspesion.001_joint" type="revolute">
    <limit lower="-0.0872664973" upper="0.0872664973" effort="0.0000000000" velocity="0.0000000000"/>
    <origin rpy="0.0000000000 0.0000000000 0.0000000000" xyz="0.0426865372 -0.0552989601 -0.0245032553"/>
    <parent link="base_link"/>
    <child link="Right_small_wheels_frame.001_link"/>
    <axis xyz="0.0000000000 1.0000000000 0.0000000000"/>
  </joint>
  <joint name="base_right_small_suspesion.002_joint" type="revolute">
    <limit lower="-0.0872664973" upper="0.0872664973" effort="0.0000000000" velocity="0.0000000000"/>
    <origin rpy="0.0000000000 0.0000000000 0.0000000000" xyz="0.0108365354 -0.0552990123 -0.0245032609"/>
    <parent link="base_link"/>
    <child link="Right_small_wheels_frame.002_link"/>
    <axis xyz="0.0000000000 1.0000000000 0.0000000000"/>
  </joint>
  <joint name="base_right_small_suspesion.003_joint" type="revolute">
    <limit lower="-0.0872664973" upper="0.0872664973" effort="0.0000000000" velocity="0.0000000000"/>
    <origin rpy="0.0000000000 0.0000000000 0.0000000000" xyz="-0.0242173222 -0.0552990048 -0.0245032609"/>
    <parent link="base_link"/>
    <child link="Right_small_wheels_frame.003_link"/>
    <axis xyz="0.0000000000 1.0000000000 0.0000000000"/>
  </joint>
  <joint name="base_right_small_suspesion.004_joint" type="revolute">
    <limit lower="-0.0872664973" upper="0.0872664973" effort="0.0000000000" velocity="0.0000000000"/>
    <origin rpy="0.0000000000 0.0000000000 0.0000000000" xyz="-0.0579519418 -0.0552989638 -0.0245032646"/>
    <parent link="base_link"/>
    <child link="Right_small_wheels_frame.004_link"/>
    <axis xyz="0.0000000000 1.0000000000 0.0000000000"/>
  </joint>
  <joint name="base_right_small_suspesion_joint" type="revolute">
    <limit lower="-0.0872664973" upper="0.0872664973" effort="0.0000000000" velocity="0.0000000000"/>
    <origin rpy="0.0000000000 0.0000000000 0.0000000000" xyz="0.0790596197 -0.0552989564 -0.0245032609"/>
    <parent link="base_link"/>
    <child link="Right_small_wheels_frame_link"/>
    <axis xyz="0.0000000000 1.0000000000 0.0000000000"/>
  </joint>
  <joint name="base_right_wheel.001_joint" type="fixed">
    <origin rpy="0.0000000000 0.0000000000 0.0000000000" xyz="-0.0102820508 -0.0209510401 -0.0114647429"/>
    <parent link="Right_small_wheels_frame.004_link"/>
    <child link="Right_wheel.001_link"/>
  </joint>
  <joint name="base_right_wheel.002_joint" type="fixed">
    <origin rpy="0.0000000000 0.0000000000 0.0000000000" xyz="-0.0096226707 -0.0209510215 -0.0114647485"/>
    <parent link="Right_small_wheels_frame.003_link"/>
    <child link="Right_wheel.002_link"/>
  </joint>
  <joint name="base_right_wheel.003_joint" type="fixed">
    <origin rpy="0.0000000000 0.0000000000 0.0000000000" xyz="-0.0108365374 -0.0209509768 -0.0114647448"/>
    <parent link="Right_small_wheels_frame.002_link"/>
    <child link="Right_wheel.003_link"/>
  </joint>
  <joint name="base_right_wheel.004_joint" type="fixed">
    <origin rpy="0.0000000000 0.0000000000 0.0000000000" xyz="-0.0091175474 -0.0209510438 -0.0114647504"/>
    <parent link="Right_small_wheels_frame.001_link"/>
    <child link="Right_wheel.004_link"/>
  </joint>
  <joint name="base_right_wheel.005_joint" type="fixed">
    <origin rpy="0.0000000000 0.0000000000 0.0000000000" xyz="-0.0103706494 -0.0209510326 -0.0114647336"/>
    <parent link="Right_small_wheels_frame_link"/>
    <child link="Right_wheel.005_link"/>
  </joint>
  <joint name="base_right_wheel.006_joint" type="fixed">
    <origin rpy="0.0000000000 0.0000000000 0.0000000000" xyz="0.1065519939 -0.0762499890 -0.0005410090"/>
    <parent link="base_link"/>
    <child link="Right_wheel.006_link"/>
  </joint>
  <joint name="base_right_wheel_sprocket_joint" type="fixed">
    <origin rpy="0.0000000000 0.0000000000 0.0000000000" xyz="-0.1065520083 -0.0762500114 -0.0005410053"/>
    <parent link="base_link"/>
    <child link="Right_wheel_sprocket_link"/>
  </joint>
  <link name="Left_small_wheels_frame.001_link">
    <collision name="Left_small_wheels_frame.001_collision">
      <origin rpy="0.0000000000 -0.7853982406 0.0000000000" xyz="0.0000000037 -0.0000000037 0.0000000000"/>
      <geometry>
        <box size="0.0494383872 0.0048000002 0.0069306139"/>
      </geometry>
    </collision>
    <inertial>
      <inertia ixx="0.0000010576" ixy="0.0000000000" ixz="-0.0000009984" iyy="0.0000020768" iyz="0.0000000000" izz="0.0000010576"/>
      <origin rpy="0.0000000000 0.0000000000 0.0000000000" xyz="0.0000000037 -0.0000000037 0.0000000000"/>
      <mass value="0.0099999998"/>
    </inertial>
    <visual name="Left_small_wheels_frame.001">
      <material name="grey" />
      <origin rpy="0.0000000000 -0.7853981563 0.0000000000" xyz="0.0000000037 -0.0000000037 0.0000000000"/>
      <geometry>
        <box size="0.0494383872 0.0048000002 0.0069306139"/>
      </geometry>
    </visual>
  </link>
  <link name="Left_small_wheels_frame.002_link">
    <collision name="Left_small_wheels_frame.002_collision">
      <origin rpy="0.0000000000 -0.7853982406 0.0000000000" xyz="0.0000000009 0.0000000037 0.0000000019"/>
      <geometry>
        <box size="0.0494383946 0.0048000012 0.0069306139"/>
      </geometry>
    </collision>
    <inertial>
      <inertia ixx="0.0000010576" ixy="0.0000000000" ixz="-0.0000009984" iyy="0.0000020768" iyz="0.0000000000" izz="0.0000010576"/>
      <origin rpy="0.0000000000 0.0000000000 0.0000000000" xyz="0.0000000019 0.0000000037 0.0000000019"/>
      <mass value="0.0099999998"/>
    </inertial>
    <visual name="Left_small_wheels_frame.002">
      <material name="grey" />
      <origin rpy="0.0000000000 -0.7853981563 0.0000000000" xyz="0.0000000019 0.0000000037 0.0000000019"/>
      <geometry>
        <box size="0.0494383946 0.0048000016 0.0069306139"/>
      </geometry>
    </visual>
  </link>
  <link name="Left_small_wheels_frame.003_link">
    <collision name="Left_small_wheels_frame.003_collision">
      <origin rpy="0.0000000000 -0.7853982406 0.0000000000" xyz="0.0000000000 0.0000000037 0.0000000019"/>
      <geometry>
        <box size="0.0494383872 0.0047999993 0.0069306139"/>
      </geometry>
    </collision>
    <inertial>
      <inertia ixx="0.0000010576" ixy="0.0000000000" ixz="-0.0000009984" iyy="0.0000020768" iyz="0.0000000000" izz="0.0000010576"/>
      <origin rpy="0.0000000000 0.0000000000 0.0000000000" xyz="0.0000000000 0.0000000037 0.0000000019"/>
      <mass value="0.0099999998"/>
    </inertial>
    <visual name="Left_small_wheels_frame.003">
      <material name="grey" />
      <origin rpy="0.0000000000 -0.7853981563 0.0000000000" xyz="0.0000000000 0.0000000037 0.0000000019"/>
      <geometry>
        <box size="0.0494383872 0.0047999993 0.0069306139"/>
      </geometry>
    </visual>
  </link>
  <link name="Left_small_wheels_frame.004_link">
    <collision name="Left_small_wheels_frame.004_collision">
      <origin rpy="-0.0000000000 -0.7853982755 -0.0000000000" xyz="-0.0000000037 0.0000000037 0.0000000037"/>
      <geometry>
        <box size="0.0494383946 0.0048000002 0.0069306148"/>
      </geometry>
    </collision>
    <inertial>
      <inertia ixx="0.0000010576" ixy="0.0000000000" ixz="-0.0000009984" iyy="0.0000020768" iyz="0.0000000000" izz="0.0000010576"/>
      <origin rpy="0.0000000000 0.0000000000 0.0000000000" xyz="-0.0000000037 0.0000000037 0.0000000019"/>
      <mass value="0.0099999998"/>
    </inertial>
    <visual name="Left_small_wheels_frame.004">
      <material name="grey" />
      <origin rpy="-0.0000000000 -0.7853983351 -0.0000000000" xyz="-0.0000000037 0.0000000037 0.0000000019"/>
      <geometry>
        <box size="0.0494383872 0.0047999998 0.0069306134"/>
      </geometry>
    </visual>
  </link>
  <link name="Left_small_wheels_frame_link">
    <collision name="Left_small_wheels_frame_collision">
      <origin rpy="0.0000000000 -0.7853982406 0.0000000000" xyz="0.0000000075 0.0000000037 0.0000000019"/>
      <geometry>
        <box size="0.0400260091 0.0048000002 0.0069306148"/>
      </geometry>
    </collision>
    <inertial>
      <inertia ixx="0.0000007067" ixy="0.0000000000" ixz="-0.0000006475" iyy="0.0000013751" iyz="0.0000000000" izz="0.0000007067"/>
      <origin rpy="0.0000000000 0.0000000000 0.0000000000" xyz="0.0000000075 0.0000000037 0.0000000019"/>
      <mass value="0.0099999998"/>
    </inertial>
    <visual name="Left_small_wheels_frame">
      <material name="grey" />
      <origin rpy="0.0000000000 -0.7853982406 0.0000000000" xyz="0.0000000075 0.0000000037 0.0000000019"/>
      <geometry>
        <box size="0.0400260054 0.0048000012 0.0069306139"/>
      </geometry>
    </visual>
  </link>
  <link name="Left_wheel.001_link">
    <collision name="Left_wheel.001_collision">
      <origin rpy="-1.5707960129 -0.0000000000 0.0000000000" xyz="0.0000000000 -0.0000000224 0.0000000019"/>
      <geometry>
        <cylinder radius="0.0150000015" length="0.0370999947"/>
      </geometry>
    </collision>
    <inertial>
      <inertia ixx="0.0000085475" ixy="0.0000000000" ixz="-0.0000000000" iyy="0.0000056250" iyz="-0.0000000000" izz="0.0000085475"/>
      <origin rpy="0.0000000000 0.0000000000 0.0000000000" xyz="0.0000000000 -0.0000000224 0.0000000019"/>
      <mass value="0.0500000007"/>
    </inertial>
    <visual name="Left_wheel.001">
      <material name="white" />
      <origin rpy="-1.5707960129 -0.0000000000 0.0000000000" xyz="0.0000000000 -0.0000000224 0.0000000019"/>
      <geometry>
        <cylinder radius="0.0149999978" length="0.0370999910"/>
      </geometry>
    </visual>
  </link>
  <link name="Left_wheel.002_link">
    <collision name="Left_wheel.002_collision">
      <origin rpy="-1.5707960129 -0.0000000000 0.0000000000" xyz="0.0000000000 -0.0000000224 0.0000000056"/>
      <geometry>
        <cylinder radius="0.0150000015" length="0.0370999947"/>
      </geometry>
    </collision>
    <inertial>
      <inertia ixx="0.0000085475" ixy="-0.0000000000" ixz="0.0000000000" iyy="0.0000056250" iyz="-0.0000000000" izz="0.0000085475"/>
      <origin rpy="0.0000000000 0.0000000000 0.0000000000" xyz="0.0000000000 -0.0000000224 0.0000000056"/>
      <mass value="0.0500000007"/>
    </inertial>
    <visual name="Left_wheel.002">
      <material name="white" />
      <origin rpy="-1.5707960129 -0.0000000000 0.0000000000" xyz="0.0000000000 -0.0000000224 0.0000000056"/>
      <geometry>
        <cylinder radius="0.0149999978" length="0.0370999910"/>
      </geometry>
    </visual>
  </link>
  <link name="Left_wheel.003_link">
    <collision name="Left_wheel.003_collision">
      <origin rpy="-1.5707960129 -0.0000000000 0.0000000000" xyz="0.0000000000 -0.0000000224 -0.0000000037"/>
      <geometry>
        <cylinder radius="0.0150000015" length="0.0370999984"/>
      </geometry>
    </collision>
    <inertial>
      <inertia ixx="0.0000085475" ixy="-0.0000000000" ixz="0.0000000000" iyy="0.0000056250" iyz="-0.0000000000" izz="0.0000085475"/>
      <origin rpy="0.0000000000 0.0000000000 0.0000000000" xyz="0.0000000000 -0.0000000224 -0.0000000019"/>
      <mass value="0.0500000007"/>
    </inertial>
    <visual name="Left_wheel.003">
      <material name="white" />
      <origin rpy="-1.5707960129 -0.0000000000 0.0000000000" xyz="0.0000000000 -0.0000000224 -0.0000000019"/>
      <geometry>
        <cylinder radius="0.0149999969" length="0.0370999910"/>
      </geometry>
    </visual>
  </link>
  <link name="Left_wheel.004_link">
    <collision name="Left_wheel.004_collision">
      <origin rpy="-1.5707960129 -0.0000000000 0.0000000000" xyz="0.0000000000 -0.0000000149 0.0000000019"/>
      <geometry>
        <cylinder radius="0.0150000015" length="0.0370999947"/>
      </geometry>
    </collision>
    <inertial>
      <inertia ixx="0.0000085475" ixy="-0.0000000000" ixz="0.0000000000" iyy="0.0000056250" iyz="-0.0000000000" izz="0.0000085475"/>
      <origin rpy="0.0000000000 0.0000000000 0.0000000000" xyz="0.0000000000 -0.0000000149 0.0000000019"/>
      <mass value="0.0500000007"/>
    </inertial>
    <visual name="Left_wheel.004">
      <material name="white" />
      <origin rpy="-1.5707960129 -0.0000000000 0.0000000000" xyz="0.0000000000 -0.0000000149 0.0000000019"/>
      <geometry>
        <cylinder radius="0.0149999987" length="0.0370999910"/>
      </geometry>
    </visual>
  </link>
  <link name="Left_wheel.005_link">
    <collision name="Left_wheel.005_collision">
      <origin rpy="-1.5707960129 -0.0000000000 0.0000000000" xyz="0.0000000075 -0.0000000075 -0.0000000037"/>
      <geometry>
        <cylinder radius="0.0150000015" length="0.0370999947"/>
      </geometry>
    </collision>
    <inertial>
      <inertia ixx="0.0000085475" ixy="-0.0000000000" ixz="0.0000000000" iyy="0.0000056250" iyz="-0.0000000000" izz="0.0000085475"/>
      <origin rpy="0.0000000000 0.0000000000 0.0000000000" xyz="0.0000000075 -0.0000000075 -0.0000000037"/>
      <mass value="0.0500000007"/>
    </inertial>
    <visual name="Left_wheel.005">
      <material name="white" />
      <origin rpy="-1.5707960129 -0.0000000000 0.0000000000" xyz="0.0000000075 -0.0000000075 -0.0000000037"/>
      <geometry>
        <cylinder radius="0.0150000006" length="0.0370999947"/>
      </geometry>
    </visual>
  </link>
  <link name="Left_wheel.006_link">
    <collision name="Left_wheel.006_collision">
      <origin rpy="-1.5707956553 0.0000000000 0.0000000000" xyz="0.0000000000 -0.0000000075 0.0000000000"/>
      <geometry>
        <cylinder radius="0.0161000006" length="0.0371000022"/>
      </geometry>
    </collision>
    <inertial>
      <inertia ixx="0.0000089752" ixy="0.0000000000" ixz="0.0000000000" iyy="0.0000064803" iyz="-0.0000000000" izz="0.0000089752"/>
      <origin rpy="0.0000000000 0.0000000000 0.0000000000" xyz="0.0000000000 -0.0000000075 0.0000000000"/>
      <mass value="0.0500000007"/>
    </inertial>
    <visual name="Left_wheel.006">
      <material name="white" />
      <origin rpy="-1.5707956553 0.0000000000 0.0000000000" xyz="0.0000000000 -0.0000000075 0.0000000000"/>
      <geometry>
        <cylinder radius="0.0161000006" length="0.0370999984"/>
      </geometry>
    </visual>
  </link>
  <link name="Left_wheel_sprocket_link">
    <collision name="Left_wheel_sprocket_collision">
      <origin rpy="-1.5707956553 0.0000000000 0.0000000000" xyz="0.0000000000 0.0000000000 -0.0000000075"/>
      <geometry>
        <cylinder radius="0.0161000006" length="0.0371000022"/>
      </geometry>
    </collision>
    <inertial>
      <inertia ixx="0.0000089752" ixy="0.0000000000" ixz="0.0000000000" iyy="0.0000064803" iyz="-0.0000000000" izz="0.0000089752"/>
      <origin rpy="0.0000000000 0.0000000000 0.0000000000" xyz="0.0000000000 0.0000000000 -0.0000000075"/>
      <mass value="0.0500000007"/>
    </inertial>
    <visual name="Left_wheel_sprocket">
      <material name="white" />
      <origin rpy="-1.5707956553 0.0000000000 0.0000000000" xyz="0.0000000000 0.0000000000 -0.0000000075"/>
      <geometry>
        <cylinder radius="0.0161000006" length="0.0370999984"/>
      </geometry>
    </visual>
  </link>
  <link name="Right_small_wheels_frame.001_link">
    <collision name="Right_small_wheels_frame.001_collision">
      <origin rpy="-0.0000000000 -0.7853982406 0.0000000000" xyz="0.0000000000 -0.0000000037 0.0000000037"/>
      <geometry>
        <box size="0.0494383946 0.0048000067 0.0069306148"/>
      </geometry>
    </collision>
    <inertial>
      <inertia ixx="0.0000010576" ixy="-0.0000000000" ixz="-0.0000009984" iyy="0.0000020768" iyz="-0.0000000000" izz="0.0000010576"/>
      <origin rpy="0.0000000000 0.0000000000 0.0000000000" xyz="0.0000000000 -0.0000000037 0.0000000037"/>
      <mass value="0.0099999998"/>
    </inertial>
    <visual name="Right_small_wheels_frame.001">
      <material name="grey" />
      <origin rpy="-0.0000000000 -0.7853982406 0.0000000000" xyz="0.0000000000 -0.0000000037 0.0000000037"/>
      <geometry>
        <box size="0.0494383872 0.0048000072 0.0069306139"/>
      </geometry>
    </visual>
  </link>
  <link name="Right_small_wheels_frame.002_link">
    <collision name="Right_small_wheels_frame.002_collision">
      <origin rpy="0.0000000000 -0.7853982406 0.0000000000" xyz="-0.0000000009 -0.0000000037 0.0000000019"/>
      <geometry>
        <box size="0.0494383946 0.0048000012 0.0069306139"/>
      </geometry>
    </collision>
    <inertial>
      <inertia ixx="0.0000010576" ixy="0.0000000000" ixz="-0.0000009984" iyy="0.0000020768" iyz="0.0000000000" izz="0.0000010576"/>
      <origin rpy="0.0000000000 0.0000000000 0.0000000000" xyz="0.0000000000 -0.0000000037 0.0000000019"/>
      <mass value="0.0099999998"/>
    </inertial>
    <visual name="Right_small_wheels_frame.002">
      <material name="grey" />
      <origin rpy="0.0000000000 -0.7853981563 0.0000000000" xyz="0.0000000000 -0.0000000037 0.0000000019"/>
      <geometry>
        <box size="0.0494383946 0.0048000016 0.0069306139"/>
      </geometry>
    </visual>
  </link>
  <link name="Right_small_wheels_frame.003_link">
    <collision name="Right_small_wheels_frame.003_collision">
      <origin rpy="-0.0000000000 -0.7853982406 0.0000000000" xyz="0.0000000000 -0.0000000037 0.0000000019"/>
      <geometry>
        <box size="0.0494383946 0.0047999993 0.0069306148"/>
      </geometry>
    </collision>
    <inertial>
      <inertia ixx="0.0000010576" ixy="-0.0000000000" ixz="-0.0000009984" iyy="0.0000020768" iyz="-0.0000000000" izz="0.0000010576"/>
      <origin rpy="0.0000000000 0.0000000000 0.0000000000" xyz="0.0000000000 -0.0000000037 0.0000000019"/>
      <mass value="0.0099999998"/>
    </inertial>
    <visual name="Right_small_wheels_frame.003">
      <material name="grey" />
      <origin rpy="-0.0000000000 -0.7853982406 0.0000000000" xyz="0.0000000000 -0.0000000037 0.0000000019"/>
      <geometry>
        <box size="0.0494383872 0.0047999998 0.0069306139"/>
      </geometry>
    </visual>
  </link>
  <link name="Right_small_wheels_frame.004_link">
    <collision name="Right_small_wheels_frame.004_collision">
      <origin rpy="-0.0000000000 -0.7853982755 -0.0000000000" xyz="-0.0000000037 0.0000000000 0.0000000019"/>
      <geometry>
        <box size="0.0494383946 0.0048000002 0.0069306148"/>
      </geometry>
    </collision>
    <inertial>
      <inertia ixx="0.0000010576" ixy="0.0000000000" ixz="-0.0000009984" iyy="0.0000020768" iyz="0.0000000000" izz="0.0000010576"/>
      <origin rpy="0.0000000000 0.0000000000 0.0000000000" xyz="-0.0000000037 0.0000000000 0.0000000000"/>
      <mass value="0.0099999998"/>
    </inertial>
    <visual name="Right_small_wheels_frame.004">
      <material name="grey" />
      <origin rpy="-0.0000000000 -0.7853983351 -0.0000000000" xyz="-0.0000000037 0.0000000000 0.0000000000"/>
      <geometry>
        <box size="0.0494383872 0.0047999998 0.0069306134"/>
      </geometry>
    </visual>
  </link>
  <link name="Right_small_wheels_frame_link">
    <collision name="Right_small_wheels_frame_collision">
      <origin rpy="0.0000000000 -0.7853982406 0.0000000000" xyz="-0.0000000075 -0.0000000037 0.0000000019"/>
      <geometry>
        <box size="0.0400260091 0.0048000002 0.0069306148"/>
      </geometry>
    </collision>
    <inertial>
      <inertia ixx="0.0000007067" ixy="0.0000000000" ixz="-0.0000006475" iyy="0.0000013751" iyz="0.0000000000" izz="0.0000007067"/>
      <origin rpy="0.0000000000 0.0000000000 0.0000000000" xyz="-0.0000000075 -0.0000000037 0.0000000019"/>
      <mass value="0.0099999998"/>
    </inertial>
    <visual name="Right_small_wheels_frame">
      <material name="grey" />
      <origin rpy="0.0000000000 -0.7853982406 0.0000000000" xyz="-0.0000000075 -0.0000000037 0.0000000019"/>
      <geometry>
        <box size="0.0400260054 0.0048000007 0.0069306139"/>
      </geometry>
    </visual>
  </link>
  <link name="Right_wheel.001_link">
    <collision name="Right_wheel.001_collision">
      <origin rpy="-1.5707960129 -0.0000000000 0.0000000000" xyz="-0.0000000075 0.0000000075 -0.0000000037"/>
      <geometry>
        <cylinder radius="0.0150000006" length="0.0371000022"/>
      </geometry>
    </collision>
    <inertial>
      <inertia ixx="0.0000085475" ixy="0.0000000000" ixz="-0.0000000000" iyy="0.0000056250" iyz="-0.0000000000" izz="0.0000085475"/>
      <origin rpy="0.0000000000 0.0000000000 0.0000000000" xyz="-0.0000000075 0.0000000075 -0.0000000037"/>
      <mass value="0.0500000007"/>
    </inertial>
    <visual name="Right_wheel.001">
      <material name="white" />
      <origin rpy="-1.5707960129 -0.0000000000 0.0000000000" xyz="-0.0000000075 0.0000000075 -0.0000000037"/>
      <geometry>
        <cylinder radius="0.0149999997" length="0.0370999984"/>
      </geometry>
    </visual>
  </link>
  <link name="Right_wheel.002_link">
    <collision name="Right_wheel.002_collision">
      <origin rpy="-1.5707960129 -0.0000000000 0.0000000000" xyz="0.0000000037 -0.0000000075 -0.0000000019"/>
      <geometry>
        <cylinder radius="0.0150000006" length="0.0371000022"/>
      </geometry>
    </collision>
    <inertial>
      <inertia ixx="0.0000085475" ixy="-0.0000000000" ixz="0.0000000000" iyy="0.0000056250" iyz="-0.0000000000" izz="0.0000085475"/>
      <origin rpy="0.0000000000 0.0000000000 0.0000000000" xyz="0.0000000037 -0.0000000075 -0.0000000019"/>
      <mass value="0.0500000007"/>
    </inertial>
    <visual name="Right_wheel.002">
      <material name="white" />
      <origin rpy="-1.5707960129 -0.0000000000 0.0000000000" xyz="0.0000000037 -0.0000000075 -0.0000000019"/>
      <geometry>
        <cylinder radius="0.0150000006" length="0.0371000022"/>
      </geometry>
    </visual>
  </link>
  <link name="Right_wheel.003_link">
    <collision name="Right_wheel.003_collision">
      <origin rpy="-1.5707960129 -0.0000000000 0.0000000000" xyz="0.0000000009 0.0000000075 -0.0000000075"/>
      <geometry>
        <cylinder radius="0.0150000006" length="0.0371000022"/>
      </geometry>
    </collision>
    <inertial>
      <inertia ixx="0.0000085475" ixy="-0.0000000000" ixz="0.0000000000" iyy="0.0000056250" iyz="-0.0000000000" izz="0.0000085475"/>
      <origin rpy="0.0000000000 0.0000000000 0.0000000000" xyz="0.0000000019 0.0000000075 -0.0000000075"/>
      <mass value="0.0500000007"/>
    </inertial>
    <visual name="Right_wheel.003">
      <material name="white" />
      <origin rpy="-1.5707960129 -0.0000000000 0.0000000000" xyz="0.0000000019 0.0000000075 -0.0000000075"/>
      <geometry>
        <cylinder radius="0.0149999997" length="0.0370999984"/>
      </geometry>
    </visual>
  </link>
  <link name="Right_wheel.004_link">
    <collision name="Right_wheel.004_collision">
      <origin rpy="-1.5707960129 -0.0000000000 0.0000000000" xyz="0.0000000075 0.0000000075 -0.0000000037"/>
      <geometry>
        <cylinder radius="0.0150000006" length="0.0371000022"/>
      </geometry>
    </collision>
    <inertial>
      <inertia ixx="0.0000085475" ixy="-0.0000000000" ixz="0.0000000000" iyy="0.0000056250" iyz="-0.0000000000" izz="0.0000085475"/>
      <origin rpy="0.0000000000 0.0000000000 0.0000000000" xyz="0.0000000075 0.0000000075 -0.0000000037"/>
      <mass value="0.0500000007"/>
    </inertial>
    <visual name="Right_wheel.004">
      <material name="white" />
      <origin rpy="-1.5707960129 -0.0000000000 0.0000000000" xyz="0.0000000075 0.0000000075 -0.0000000037"/>
      <geometry>
        <cylinder radius="0.0150000006" length="0.0371000022"/>
      </geometry>
    </visual>
  </link>
  <link name="Right_wheel.005_link">
    <collision name="Right_wheel.005_collision">
      <origin rpy="-1.5707960129 -0.0000000000 0.0000000000" xyz="0.0000000000 0.0000000000 0.0000000019"/>
      <geometry>
        <cylinder radius="0.0150000006" length="0.0371000022"/>
      </geometry>
    </collision>
    <inertial>
      <inertia ixx="0.0000085475" ixy="-0.0000000000" ixz="0.0000000000" iyy="0.0000056250" iyz="-0.0000000000" izz="0.0000085475"/>
      <origin rpy="0.0000000000 0.0000000000 0.0000000000" xyz="0.0000000000 0.0000000000 0.0000000019"/>
      <mass value="0.0500000007"/>
    </inertial>
    <visual name="Right_wheel.005">
      <material name="white" />
      <origin rpy="-1.5707960129 -0.0000000000 0.0000000000" xyz="0.0000000000 0.0000000000 0.0000000019"/>
      <geometry>
        <cylinder radius="0.0150000006" length="0.0371000022"/>
      </geometry>
    </visual>
  </link>
  <link name="Right_wheel.006_link">
    <collision name="Right_wheel.006_collision">
      <origin rpy="-1.5707956553 0.0000000000 0.0000000000" xyz="-0.0000000075 -0.0000000075 0.0000000037"/>
      <geometry>
        <cylinder radius="0.0161000006" length="0.0370999947"/>
      </geometry>
    </collision>
    <inertial>
      <inertia ixx="0.0000089752" ixy="-0.0000000000" ixz="-0.0000000000" iyy="0.0000064802" iyz="-0.0000000000" izz="0.0000089752"/>
      <origin rpy="0.0000000000 0.0000000000 0.0000000000" xyz="-0.0000000075 -0.0000000075 0.0000000037"/>
      <mass value="0.0500000007"/>
    </inertial>
    <visual name="Right_wheel.006">
      <material name="white" />
      <origin rpy="-1.5707956553 0.0000000000 0.0000000000" xyz="-0.0000000075 -0.0000000075 0.0000000037"/>
      <geometry>
        <cylinder radius="0.0160999987" length="0.0370999910"/>
      </geometry>
    </visual>
  </link>
  <link name="Right_wheel_sprocket_link">
    <collision name="Right_wheel_sprocket_collision">
      <origin rpy="-1.5707956553 0.0000000000 0.0000000000" xyz="0.0000000000 0.0000000000 0.0000000037"/>
      <geometry>
        <cylinder radius="0.0161000006" length="0.0370999947"/>
      </geometry>
    </collision>
    <inertial>
      <inertia ixx="0.0000089752" ixy="-0.0000000000" ixz="-0.0000000000" iyy="0.0000064802" iyz="-0.0000000000" izz="0.0000089752"/>
      <origin rpy="0.0000000000 0.0000000000 0.0000000000" xyz="0.0000000000 0.0000000000 0.0000000037"/>
      <mass value="0.0500000007"/>
    </inertial>
    <visual name="Right_wheel_sprocket">
      <material name="white" />
      <origin rpy="-1.5707956553 0.0000000000 0.0000000000" xyz="0.0000000000 0.0000000000 0.0000000037"/>
      <geometry>
        <cylinder radius="0.0160999987" length="0.0370999910"/>
      </geometry>
    </visual>
  </link>
  <link name="base_footprint"/>
  <link name="base_link">
    <collision name="base_collision">
      <origin rpy="0.0000000000 0.0000000000 0.0000000000" xyz="-0.0000000000 -0.0000000000 -0.0000000075"/>
      <geometry>
        <box size="0.2480000108 0.1058000028 0.0401000008"/>
      </geometry>
    </collision>
    <inertial>
      <inertia ixx="0.0010668042" ixy="0.0000000000" ixz="0.0000000000" iyy="0.0052593346" iyz="0.0000000000" izz="0.0060581372"/>
      <origin rpy="0.0000000000 0.0000000000 0.0000000000" xyz="-0.0000000000 -0.0000000000 -0.0000000075"/>
      <mass value="1.0000000000"/>
    </inertial>
    <visual name="base">
      <material name="black" />
      <origin rpy="0.0000000000 0.0000000000 0.0000000000" xyz="-0.0000000000 -0.0000000000 -0.0000000075"/>
      <geometry>
        <box size="0.2480000108 0.1058000028 0.0401000008"/>
      </geometry>
    </visual>
  </link>
  <link name="laser_link">
    <collision name="laser_collision">
      <origin rpy="0.0000000000 0.0000000000 0.0000000000" xyz="0.0000000000 -0.0000000000 -0.0000000075"/>
      <geometry>
        <cylinder radius="0.0170875005" length="0.0413499996"/>
      </geometry>
    </collision>
    <inertial>
      <inertia ixx="0.0000538702" ixy="0.0000000000" ixz="0.0000000000" iyy="0.0000538702" iyz="0.0000000000" izz="0.0000364978"/>
      <origin rpy="0.0000000000 0.0000000000 0.0000000000" xyz="0.0000000000 -0.0000000000 -0.0000000075"/>
      <mass value="0.2500000000"/>
    </inertial>
    <visual name="laser">
      <material name="red" />
      <origin rpy="0.0000000000 0.0000000000 0.0000000000" xyz="0.0000000000 -0.0000000000 -0.0000000075"/>
      <geometry>
        <cylinder radius="0.0170875005" length="0.0413499996"/>
      </geometry>
    </visual>
  </link>
</robot>