<robot name="uWABA" version="1.0">
<!-- THIS IS SOME CHANGES -->

  <material name="grey">
    <color rgba="0.5 0.5 0.5 1" />
  </material>

  <material name="blue">
    <color rgba="0 0 0.5 1" />
  </material>

  <material name="black">
    <color rgba="0.25 0.25 0.25 1" />
  </material>

  <joint name="LiDAR_base_joint" type="fixed">
    <origin rpy="0.00000 0.00000 0.00000" xyz="-0.00000 -0.00000 0.04010" />
    <parent link="base_link" />
    <child link="LiDAR_link" />
  </joint>
  <joint name="base_footprint_link_joint" type="fixed">
    <origin rpy="0.00000 0.00000 0.00000" xyz="0.00000 0.00000 0.03318" />
    <parent link="base_footprint" />
    <child link="base_link" />
  </joint>
  <joint name="left_frame_001_base_joint" type="revolute">
    <limit lower="-0.08727" upper="0.08727" effort="0.00000" velocity="0.00000" />
    <origin rpy="0.00000 0.00000 0.00000" xyz="-0.05400 0.05290 0.00682" />
    <parent link="base_link" />
    <child link="left_small_wheels_frame.001_link" />
    <axis xyz="0.00000 1.00000 0.00000" />
  </joint>
  <joint name="left_frame_002_base_joint" type="revolute">
    <limit lower="-0.08727" upper="0.08727" effort="0.00000" velocity="0.00000" />
    <origin rpy="0.00000 0.00000 0.00000" xyz="-0.02250 0.05290 0.00682" />
    <parent link="base_link" />
    <child link="left_small_wheels_frame.002_link" />
    <axis xyz="0.00000 1.00000 0.00000" />
  </joint>
  <joint name="left_frame_003_base_joint" type="revolute">
    <limit lower="-0.08727" upper="0.08727" effort="0.00000" velocity="0.00000" />
    <origin rpy="0.00000 0.00000 0.00000" xyz="0.01250 0.05290 0.00682" />
    <parent link="base_link" />
    <child link="left_small_wheels_frame.003_link" />
    <axis xyz="0.00000 1.00000 0.00000" />
  </joint>
  <joint name="left_frame_004_base_joint" type="revolute">
    <limit lower="-0.08727" upper="0.08727" effort="0.00000" velocity="0.00000" />
    <origin rpy="0.00000 0.00000 0.00000" xyz="0.04659 0.05290 0.00682" />
    <parent link="base_link" />
    <child link="left_small_wheels_frame.004_link" />
    <axis xyz="0.00000 1.00000 0.00000" />
  </joint>
  <joint name="left_frame_base_joint" type="revolute">
    <limit lower="-0.08727" upper="0.08727" effort="0.00000" velocity="0.00000" />
    <origin rpy="0.00000 0.00000 0.00000" xyz="-0.09000 0.05290 0.00682" />
    <parent link="base_link" />
    <child link="left_small_wheels_frame_link" />
    <axis xyz="0.00000 1.00000 0.00000" />
  </joint>
  <joint name="left_small_wheel_001_joint" type="fixed">
    <origin rpy="0.00000 0.00000 0.00000" xyz="0.02164 0.00480 -0.02274" />
    <parent link="left_small_wheels_frame.004_link" />
    <child link="left_wheel.001_link" />
  </joint>
  <joint name="left_small_wheel_002_joint" type="fixed">
    <origin rpy="0.00000 0.00000 0.00000" xyz="0.02134 0.00480 -0.02274" />
    <parent link="left_small_wheels_frame.003_link" />
    <child link="left_wheel.002_link" />
  </joint>
  <joint name="left_small_wheel_003_joint" type="fixed">
    <origin rpy="0.00000 0.00000 0.00000" xyz="0.02250 0.00480 -0.02274" />
    <parent link="left_small_wheels_frame.002_link" />
    <child link="left_wheel.003_link" />
  </joint>
  <joint name="left_small_wheel_004_joint" type="fixed">
    <origin rpy="0.00000 0.00000 0.00000" xyz="0.02043 0.00480 -0.02274" />
    <parent link="left_small_wheels_frame.001_link" />
    <child link="left_wheel.004_link" />
  </joint>
  <joint name="left_small_wheel_005_joint" type="fixed">
    <origin rpy="0.00000 0.00000 0.00000" xyz="0.02131 0.00480 -0.02274" />
    <parent link="left_small_wheels_frame_link" />
    <child link="left_wheel.005_link" />
  </joint>
  <joint name="left_sprocket_base_joint" type="continuous">
    <limit lower="0.00000" upper="0.00000" effort="0.00000" velocity="0.00000" />
    <origin rpy="0.00000 0.00000 0.00000" xyz="0.10655 0.05770 0.01951" />
    <parent link="base_link" />
    <child link="left_wheel_sprocket_link" />
    <axis xyz="0.00000 1.00000 0.00000" />
  </joint>
  <!-- <joint name="left_treads_base_joint" type="fixed">
    <origin rpy="0.00000 0.00000 0.00000" xyz="-0.00000 0.07658 0.03682" />
    <parent link="base_link" />
    <child link="left_bumped_treads_link" />
  </joint> -->
  <joint name="left_wheel_006_base_joint" type="fixed">
    <origin rpy="0.00000 0.00000 0.00000" xyz="-0.10655 0.05770 0.01951" />
    <parent link="base_link" />
    <child link="left_wheel.006_link" />
  </joint>
  <joint name="right_frame_001_base_joint" type="revolute">
    <limit lower="-0.08727" upper="0.08727" effort="0.00000" velocity="0.00000" />
    <origin rpy="0.00000 0.00000 0.00000" xyz="-0.05400 -0.05290 0.00682" />
    <parent link="base_link" />
    <child link="right_small_wheels_frame.001_link" />
    <axis xyz="0.00000 1.00000 0.00000" />
  </joint>
  <joint name="right_frame_002_base_joint" type="revolute">
    <limit lower="-0.08727" upper="0.08727" effort="0.00000" velocity="0.00000" />
    <origin rpy="0.00000 0.00000 0.00000" xyz="-0.02250 -0.05290 0.00682" />
    <parent link="base_link" />
    <child link="right_small_wheels_frame.002_link" />
    <axis xyz="0.00000 1.00000 0.00000" />
  </joint>
  <joint name="right_frame_003_base_joint" type="revolute">
    <limit lower="-0.08727" upper="0.08727" effort="0.00000" velocity="0.00000" />
    <origin rpy="0.00000 0.00000 0.00000" xyz="0.01250 -0.05290 0.00682" />
    <parent link="base_link" />
    <child link="right_small_wheels_frame.003_link" />
    <axis xyz="0.00000 1.00000 0.00000" />
  </joint>
  <joint name="right_frame_004_base_joint" type="revolute">
    <limit lower="-0.08727" upper="0.08727" effort="0.00000" velocity="0.00000" />
    <origin rpy="0.00000 0.00000 0.00000" xyz="0.04659 -0.05290 0.00682" />
    <parent link="base_link" />
    <child link="right_small_wheels_frame.004_link" />
    <axis xyz="0.00000 1.00000 0.00000" />
  </joint>
  <joint name="right_frame_base_joint" type="revolute">
    <limit lower="-0.08727" upper="0.08727" effort="0.00000" velocity="0.00000" />
    <origin rpy="0.00000 0.00000 0.00000" xyz="-0.09000 -0.05290 0.00682" />
    <parent link="base_link" />
    <child link="right_small_wheels_frame_link" />
    <axis xyz="0.00000 1.00000 0.00000" />
  </joint>
  <joint name="right_small_wheel_001_joint" type="fixed">
    <origin rpy="0.00000 0.00000 0.00000" xyz="0.02164 -0.00480 -0.02274" />
    <parent link="right_small_wheels_frame.004_link" />
    <child link="right_wheel.001_link" />
  </joint>
  <joint name="right_small_wheel_002_joint" type="fixed">
    <origin rpy="0.00000 0.00000 0.00000" xyz="0.02134 -0.00480 -0.02273" />
    <parent link="right_small_wheels_frame.003_link" />
    <child link="right_wheel.002_link" />
  </joint>
  <joint name="right_small_wheel_003_joint" type="fixed">
    <origin rpy="0.00000 0.00000 0.00000" xyz="0.02250 -0.00480 -0.02273" />
    <parent link="right_small_wheels_frame.002_link" />
    <child link="right_wheel.003_link" />
  </joint>
  <joint name="right_small_wheel_004_joint" type="fixed">
    <origin rpy="0.00000 0.00000 0.00000" xyz="0.02043 -0.00480 -0.02274" />
    <parent link="right_small_wheels_frame.001_link" />
    <child link="right_wheel.004_link" />
  </joint>
  <joint name="right_small_wheel_005_joint" type="fixed">
    <origin rpy="0.00000 0.00000 0.00000" xyz="0.02131 -0.00480 -0.02274" />
    <parent link="right_small_wheels_frame_link" />
    <child link="right_wheel.005_link" />
  </joint>
  <joint name="right_sprocket_base_joint" type="continuous">
    <limit lower="0.00000" upper="0.00000" effort="0.00000" velocity="0.00000" />
    <origin rpy="0.00000 0.00000 0.00000" xyz="0.10655 -0.05770 0.01951" />
    <parent link="base_link" />
    <child link="right_wheel_sprocket_link" />
    <axis xyz="0.00000 1.00000 0.00000" />
  </joint>
  <!-- <joint name="right_treads_base_joint" type="fixed">
    <origin rpy="0.00000 0.00000 0.00000" xyz="-0.00000 -0.07625 0.03682" />
    <parent link="base_link" />
    <child link="right_bumped_treads_link" />
  </joint> -->
  <joint name="right_wheel_006_base_joint" type="fixed">
    <origin rpy="0.00000 0.00000 0.00000" xyz="-0.10655 -0.05770 0.01951" />
    <parent link="base_link" />
    <child link="right_wheel.006_link" />
  </joint>
  <link name="LiDAR_link">
    <collision name="LiDAR_collision">
      <origin rpy="0.00000 0.00000 0.00000" xyz="0.00000 -0.00000 0.02580" />
      <geometry>
        <cylinder radius="0.03420" length="0.05160" />
      </geometry>
    </collision>
    <inertial>
      <inertia ixx="0.00051" ixy="0.00000" ixz="0.00000" iyy="0.00051" iyz="0.00000" izz="0.00058" />
      <origin rpy="0.00000 0.00000 0.00000" xyz="0.00000 -0.00000 0.02580" />
      <mass value="1.00000" />
    </inertial>
    <visual name="LiDAR">
      <material name="grey" />
      <origin rpy="0.00000 0.00000 0.00000" xyz="0.00000 -0.00000 0.02580" />
      <geometry>
        <cylinder radius="0.03420" length="0.05160" />
      </geometry>
    </visual>
  </link>
  <link name="base_footprint" />
  <link name="base_link">
    <collision name="base_collision">
      <origin rpy="0.00000 0.00000 0.00000" xyz="0.00000 0.00000 0.02005" />
      <geometry>
        <box size="0.24800 0.10580 0.04010" />
      </geometry>
    </collision>
    <inertial>
      <inertia ixx="0.00107" ixy="0.00000" ixz="0.00000" iyy="0.00526" iyz="0.00000" izz="0.00606" />
      <origin rpy="0.00000 0.00000 0.00000" xyz="0.00000 0.00000 0.02005" />
      <mass value="1.00000" />
    </inertial>
    <visual name="base">
      <material name="blue" />
      <origin rpy="0.00000 0.00000 0.00000" xyz="0.00000 0.00000 0.02005" />
      <geometry>
        <box size="0.24800 0.10580 0.04010" />
      </geometry>
    </visual>
  </link>
  <!-- <link name="left_bumped_treads_link">
    <collision name="left_bumped_treads_collision">
      <origin rpy="0.00000 0.00000 0.00000" xyz="-0.00000 -0.00000 0.00000" />
      <geometry>
        <mesh filename="../meshes/dae/left.tracks.dae" scale="1.00000 1.00000 1.00000" />
      </geometry>
    </collision>
    <visual name="left_bumped_treads">
      <origin rpy="0.00000 0.00000 0.00000" xyz="-0.00000 0.00000 0.00000" />
      <geometry>
        <mesh filename="../meshes/dae/left.tracks.dae" scale="1.00000 1.00000 1.00000" />
      </geometry>
    </visual>
  </link> -->
  <link name="left_small_wheels_frame.001_link">
    <collision name="left_small_wheels_frame.001_collision">
      <origin rpy="3.14159 -0.78540 -3.14159" xyz="0.01131 0.00240 -0.01127" />
      <geometry>
        <box size="0.04944 0.00480 0.00693" />
      </geometry>
    </collision>
    <inertial>
      <inertia ixx="0.00011" ixy="0.00000" ixz="0.00010" iyy="0.00021" iyz="0.00000" izz="0.00011" />
      <origin rpy="0.00000 0.00000 0.00000" xyz="0.00000 0.00000 0.00000" />
      <mass value="1.00000" />
    </inertial>
    <visual name="left_small_wheels_frame.001">
      <material name="grey" />
      <origin rpy="3.14159 -0.78540 -3.14159" xyz="0.00000 0.00000 0.00000" />
      <geometry>
        <box size="0.04944 0.00480 0.00693" />
      </geometry>
    </visual>
  </link>
  <link name="left_small_wheels_frame.002_link">
    <collision name="left_small_wheels_frame.002_collision">
      <origin rpy="3.14159 -0.78540 -3.14159" xyz="0.01166 0.00240 -0.01127" />
      <geometry>
        <box size="0.04944 0.00480 0.00693" />
      </geometry>
    </collision>
    <inertial>
      <inertia ixx="0.00011" ixy="0.00000" ixz="0.00010" iyy="0.00021" iyz="0.00000" izz="0.00011" />
      <origin rpy="0.00000 0.00000 0.00000" xyz="0.00000 0.00000 0.00000" />
      <mass value="1.00000" />
    </inertial>
    <visual name="left_small_wheels_frame.002">
      <material name="grey" />
      <origin rpy="3.14159 -0.78540 -3.14159" xyz="0.00000 0.00000 0.00000" />
      <geometry>
        <box size="0.04944 0.00480 0.00693" />
      </geometry>
    </visual>
  </link>
  <link name="left_small_wheels_frame.003_link">
    <collision name="left_small_wheels_frame.003_collision">
      <origin rpy="3.14159 -0.78540 -3.14159" xyz="0.01172 0.00240 -0.01127" />
      <geometry>
        <box size="0.04944 0.00480 0.00693" />
      </geometry>
    </collision>
    <inertial>
      <inertia ixx="0.00011" ixy="0.00000" ixz="0.00010" iyy="0.00021" iyz="0.00000" izz="0.00011" />
      <origin rpy="0.00000 0.00000 0.00000" xyz="0.00000 0.00000 0.00000" />
      <mass value="1.00000" />
    </inertial>
    <visual name="left_small_wheels_frame.003">
      <material name="grey" />
      <origin rpy="3.14159 -0.78540 -3.14159" xyz="0.00000 0.00000 0.00000" />
      <geometry>
        <box size="0.04944 0.00480 0.00693" />
      </geometry>
    </visual>
  </link>
  <link name="left_small_wheels_frame.004_link">
    <collision name="left_small_wheels_frame.004_collision">
      <origin rpy="-3.14159 -0.78540 3.14159" xyz="0.01136 0.00240 -0.01127" />
      <geometry>
        <box size="0.04944 0.00480 0.00693" />
      </geometry>
    </collision>
    <inertial>
      <inertia ixx="0.00011" ixy="0.00000" ixz="0.00010" iyy="0.00021" iyz="0.00000" izz="0.00011" />
      <origin rpy="0.00000 0.00000 0.00000" xyz="-0.00000 -0.00000 -0.00000" />
      <mass value="1.00000" />
    </inertial>
    <visual name="left_small_wheels_frame.004">
      <material name="grey" />
      <origin rpy="-3.14159 -0.78540 3.14159" xyz="-0.00000 -0.00000 -0.00000" />
      <geometry>
        <box size="0.04944 0.00480 0.00693" />
      </geometry>
    </visual>
  </link>
  <link name="left_small_wheels_frame_link">
    <collision name="left_small_wheels_frame_collision">
      <origin rpy="3.14159 -0.78540 3.14159" xyz="0.01094 0.00240 -0.01127" />
      <geometry>
        <box size="0.04003 0.00480 0.00693" />
      </geometry>
    </collision>
    <inertial>
      <inertia ixx="0.00007" ixy="0.00000" ixz="0.00006" iyy="0.00014" iyz="0.00000" izz="0.00007" />
      <origin rpy="0.00000 0.00000 0.00000" xyz="0.00000 0.00000 0.00000" />
      <mass value="1.00000" />
    </inertial>
    <visual name="left_small_wheels_frame">
      <material name="grey" />
      <origin rpy="3.14159 -0.78540 3.14159" xyz="0.00000 0.00000 0.00000" />
      <geometry>
        <box size="0.04003 0.00480 0.00693" />
      </geometry>
    </visual>
  </link>
  <link name="left_wheel.001_link">
    <collision name="left_wheel.001_collision">
      <origin rpy="-1.57080 0.00000 0.00000" xyz="-0.00000 0.01855 0.00000" />
      <geometry>
        <cylinder radius="0.01500" length="0.03710" />
      </geometry>
    </collision>
    <inertial>
      <inertia ixx="0.00017" ixy="0.00000" ixz="0.00000" iyy="0.00011" iyz="-0.00000" izz="0.00017" />
      <origin rpy="0.00000 0.00000 0.00000" xyz="-0.00000 0.01855 0.00000" />
      <mass value="1.00000" />
    </inertial>
    <visual name="left_wheel.001">
      <material name="black" />
      <origin rpy="-1.57080 0.00000 0.00000" xyz="-0.00000 0.01855 0.00000" />
      <geometry>
        <cylinder radius="0.01500" length="0.03710" />
      </geometry>
    </visual>
  </link>
  <link name="left_wheel.002_link">
    <collision name="left_wheel.002_collision">
      <origin rpy="-1.57080 0.00000 0.00000" xyz="0.00000 0.01855 0.00000" />
      <geometry>
        <cylinder radius="0.01500" length="0.03710" />
      </geometry>
    </collision>
    <inertial>
      <inertia ixx="0.00017" ixy="0.00000" ixz="0.00000" iyy="0.00011" iyz="-0.00000" izz="0.00017" />
      <origin rpy="0.00000 0.00000 0.00000" xyz="0.00000 0.01855 0.00000" />
      <mass value="1.00000" />
    </inertial>
    <visual name="left_wheel.002">
      <material name="black" />
      <origin rpy="-1.57080 0.00000 0.00000" xyz="0.00000 0.01855 0.00000" />
      <geometry>
        <cylinder radius="0.01500" length="0.03710" />
      </geometry>
    </visual>
  </link>
  <link name="left_wheel.003_link">
    <collision name="left_wheel.003_collision">
      <origin rpy="-1.57080 0.00000 0.00000" xyz="-0.00000 0.01855 0.00000" />
      <geometry>
        <cylinder radius="0.01500" length="0.03710" />
      </geometry>
    </collision>
    <inertial>
      <inertia ixx="0.00017" ixy="0.00000" ixz="0.00000" iyy="0.00011" iyz="-0.00000" izz="0.00017" />
      <origin rpy="0.00000 0.00000 0.00000" xyz="-0.00000 0.01855 0.00000" />
      <mass value="1.00000" />
    </inertial>
    <visual name="left_wheel.003">
      <material name="black" />
      <origin rpy="-1.57080 0.00000 0.00000" xyz="-0.00000 0.01855 0.00000" />
      <geometry>
        <cylinder radius="0.01500" length="0.03710" />
      </geometry>
    </visual>
  </link>
  <link name="left_wheel.004_link">
    <collision name="left_wheel.004_collision">
      <origin rpy="-1.57080 0.00000 0.00000" xyz="-0.00000 0.01855 0.00000" />
      <geometry>
        <cylinder radius="0.01500" length="0.03710" />
      </geometry>
    </collision>
    <inertial>
      <inertia ixx="0.00017" ixy="0.00000" ixz="0.00000" iyy="0.00011" iyz="-0.00000" izz="0.00017" />
      <origin rpy="0.00000 0.00000 0.00000" xyz="-0.00000 0.01855 0.00000" />
      <mass value="1.00000" />
    </inertial>
    <visual name="left_wheel.004">
      <material name="black" />
      <origin rpy="-1.57080 0.00000 0.00000" xyz="-0.00000 0.01855 0.00000" />
      <geometry>
        <cylinder radius="0.01500" length="0.03710" />
      </geometry>
    </visual>
  </link>
  <link name="left_wheel.005_link">
    <collision name="left_wheel.005_collision">
      <origin rpy="-1.57080 0.00000 0.00000" xyz="0.00000 0.01855 0.00000" />
      <geometry>
        <cylinder radius="0.01500" length="0.03710" />
      </geometry>
    </collision>
    <inertial>
      <inertia ixx="0.00017" ixy="0.00000" ixz="0.00000" iyy="0.00011" iyz="-0.00000" izz="0.00017" />
      <origin rpy="0.00000 0.00000 0.00000" xyz="0.00000 0.01855 0.00000" />
      <mass value="1.00000" />
    </inertial>
    <visual name="left_wheel.005">
      <material name="black" />
      <origin rpy="-1.57080 0.00000 0.00000" xyz="0.00000 0.01855 0.00000" />
      <geometry>
        <cylinder radius="0.01500" length="0.03710" />
      </geometry>
    </visual>
  </link>
  <link name="left_wheel.006_link">
    <collision name="left_wheel.006_collision">
      <origin rpy="-1.57080 0.00000 0.00000" xyz="0.00000 0.01855 0.00000" />
      <geometry>
        <cylinder radius="0.01610" length="0.03710" />
      </geometry>
    </collision>
    <inertial>
      <inertia ixx="0.00018" ixy="0.00000" ixz="0.00000" iyy="0.00013" iyz="-0.00000" izz="0.00018" />
      <origin rpy="0.00000 0.00000 0.00000" xyz="0.00000 0.01855 0.00000" />
      <mass value="1.00000" />
    </inertial>
    <visual name="left_wheel.006">
      <material name="black" />
      <origin rpy="-1.57080 0.00000 0.00000" xyz="0.00000 0.01855 0.00000" />
      <geometry>
        <cylinder radius="0.01610" length="0.03710" />
      </geometry>
    </visual>
  </link>
  <link name="left_wheel_sprocket_link">
    <collision name="left_wheel_sprocket_collision">
      <origin rpy="-1.57080 0.00000 0.00000" xyz="0.00000 0.01855 0.00000" />
      <geometry>
        <cylinder radius="0.01610" length="0.03710" />
      </geometry>
    </collision>
    <inertial>
      <inertia ixx="0.00018" ixy="0.00000" ixz="0.00000" iyy="0.00013" iyz="-0.00000" izz="0.00018" />
      <origin rpy="0.00000 0.00000 0.00000" xyz="0.00000 0.01855 0.00000" />
      <mass value="1.00000" />
    </inertial>
    <visual name="left_wheel_sprocket">
      <material name="black" />
      <origin rpy="-1.57080 0.00000 0.00000" xyz="0.00000 0.01855 0.00000" />
      <geometry>
        <cylinder radius="0.01610" length="0.03710" />
      </geometry>
    </visual>
  </link>
  <!-- <link name="right_bumped_treads_link">
    <collision name="right_bumped_treads_collision">
      <origin rpy="0.00000 0.00000 0.00000" xyz="0.00000 0.00000 0.00000" />
      <geometry>
        <mesh filename="../meshes/dae/right.tracks.dae" scale="1.00000 1.00000 1.00000" />
      </geometry>
    </collision>
    <visual name="right_bumped_treads">
      <origin rpy="0.00000 0.00000 0.00000" xyz="0.00000 0.00000 0.00000" />
      <geometry>
        <mesh filename="../meshes/dae/right.tracks.dae" scale="1.00000 1.00000 1.00000" />
      </geometry>
    </visual>
  </link> -->
  <link name="right_small_wheels_frame.001_link">
    <collision name="right_small_wheels_frame.001_collision">
      <origin rpy="3.14159 -0.78540 -3.14159" xyz="0.01131 -0.00240 -0.01127" />
      <geometry>
        <box size="0.04944 0.00480 0.00693" />
      </geometry>
    </collision>
    <inertial>
      <inertia ixx="0.00011" ixy="0.00000" ixz="0.00010" iyy="0.00021" iyz="0.00000" izz="0.00011" />
      <origin rpy="0.00000 0.00000 0.00000" xyz="0.00000 -0.00000 0.00000" />
      <mass value="1.00000" />
    </inertial>
    <visual name="right_small_wheels_frame.001">
      <material name="grey" />
      <origin rpy="3.14159 -0.78540 -3.14159" xyz="0.00000 -0.00000 0.00000" />
      <geometry>
        <box size="0.04944 0.00480 0.00693" />
      </geometry>
    </visual>
  </link>
  <link name="right_small_wheels_frame.002_link">
    <collision name="right_small_wheels_frame.002_collision">
      <origin rpy="3.14159 -0.78540 -3.14159" xyz="0.01166 -0.00240 -0.01127" />
      <geometry>
        <box size="0.04944 0.00480 0.00693" />
      </geometry>
    </collision>
    <inertial>
      <inertia ixx="0.00011" ixy="0.00000" ixz="0.00010" iyy="0.00021" iyz="0.00000" izz="0.00011" />
      <origin rpy="0.00000 0.00000 0.00000" xyz="-0.00000 0.00000 0.00000" />
      <mass value="1.00000" />
    </inertial>
    <visual name="right_small_wheels_frame.002">
      <material name="grey" />
      <origin rpy="3.14159 -0.78540 -3.14159" xyz="-0.00000 0.00000 0.00000" />
      <geometry>
        <box size="0.04944 0.00480 0.00693" />
      </geometry>
    </visual>
  </link>
  <link name="right_small_wheels_frame.003_link">
    <collision name="right_small_wheels_frame.003_collision">
      <origin rpy="3.14159 -0.78540 -3.14159" xyz="0.01172 -0.00240 -0.01127" />
      <geometry>
        <box size="0.04944 0.00480 0.00693" />
      </geometry>
    </collision>
    <inertial>
      <inertia ixx="0.00011" ixy="0.00000" ixz="0.00010" iyy="0.00021" iyz="0.00000" izz="0.00011" />
      <origin rpy="0.00000 0.00000 0.00000" xyz="0.00000 -0.00000 0.00000" />
      <mass value="1.00000" />
    </inertial>
    <visual name="right_small_wheels_frame.003">
      <material name="grey" />
      <origin rpy="3.14159 -0.78540 -3.14159" xyz="0.00000 -0.00000 0.00000" />
      <geometry>
        <box size="0.04944 0.00480 0.00693" />
      </geometry>
    </visual>
  </link>
  <link name="right_small_wheels_frame.004_link">
    <collision name="right_small_wheels_frame.004_collision">
      <origin rpy="-3.14159 -0.78540 3.14159" xyz="0.01136 -0.00240 -0.01127" />
      <geometry>
        <box size="0.04944 0.00480 0.00693" />
      </geometry>
    </collision>
    <inertial>
      <inertia ixx="0.00011" ixy="0.00000" ixz="0.00010" iyy="0.00021" iyz="0.00000" izz="0.00011" />
      <origin rpy="0.00000 0.00000 0.00000" xyz="-0.00000 0.00000 -0.00000" />
      <mass value="1.00000" />
    </inertial>
    <visual name="right_small_wheels_frame.004">
      <material name="grey" />
      <origin rpy="-3.14159 -0.78540 3.14159" xyz="-0.00000 0.00000 -0.00000" />
      <geometry>
        <box size="0.04944 0.00480 0.00693" />
      </geometry>
    </visual>
  </link>
  <link name="right_small_wheels_frame_link">
    <collision name="right_small_wheels_frame_collision">
      <origin rpy="-3.14159 -0.78540 3.14159" xyz="0.01094 -0.00240 -0.01127" />
      <geometry>
        <box size="0.04003 0.00480 0.00693" />
      </geometry>
    </collision>
    <inertial>
      <inertia ixx="0.00007" ixy="0.00000" ixz="0.00006" iyy="0.00014" iyz="0.00000" izz="0.00007" />
      <origin rpy="0.00000 0.00000 0.00000" xyz="0.00000 0.00000 0.00000" />
      <mass value="1.00000" />
    </inertial>
    <visual name="right_small_wheels_frame">
      <material name="grey" />
      <origin rpy="-3.14159 -0.78540 3.14159" xyz="0.00000 0.00000 0.00000" />
      <geometry>
        <box size="0.04003 0.00480 0.00693" />
      </geometry>
    </visual>
  </link>
  <link name="right_wheel.001_link">
    <collision name="right_wheel.001_collision">
      <origin rpy="-1.57080 0.00000 0.00000" xyz="-0.00000 -0.01855 -0.00000" />
      <geometry>
        <cylinder radius="0.01500" length="0.03710" />
      </geometry>
    </collision>
    <inertial>
      <inertia ixx="0.00017" ixy="0.00000" ixz="0.00000" iyy="0.00011" iyz="-0.00000" izz="0.00017" />
      <origin rpy="0.00000 0.00000 0.00000" xyz="-0.00000 -0.01855 -0.00000" />
      <mass value="1.00000" />
    </inertial>
    <visual name="right_wheel.001">
      <material name="black" />
      <origin rpy="-1.57080 0.00000 0.00000" xyz="-0.00000 -0.01855 -0.00000" />
      <geometry>
        <cylinder radius="0.01500" length="0.03710" />
      </geometry>
    </visual>
  </link>
  <link name="right_wheel.002_link">
    <collision name="right_wheel.002_collision">
      <origin rpy="-1.57080 0.00000 0.00000" xyz="-0.00000 -0.01855 -0.00000" />
      <geometry>
        <cylinder radius="0.01500" length="0.03710" />
      </geometry>
    </collision>
    <inertial>
      <inertia ixx="0.00017" ixy="0.00000" ixz="0.00000" iyy="0.00011" iyz="-0.00000" izz="0.00017" />
      <origin rpy="0.00000 0.00000 0.00000" xyz="-0.00000 -0.01855 -0.00000" />
      <mass value="1.00000" />
    </inertial>
    <visual name="right_wheel.002">
      <material name="black" />
      <origin rpy="-1.57080 0.00000 0.00000" xyz="-0.00000 -0.01855 -0.00000" />
      <geometry>
        <cylinder radius="0.01500" length="0.03710" />
      </geometry>
    </visual>
  </link>
  <link name="right_wheel.003_link">
    <collision name="right_wheel.003_collision">
      <origin rpy="-1.57080 0.00000 0.00000" xyz="0.00000 -0.01855 -0.00000" />
      <geometry>
        <cylinder radius="0.01500" length="0.03710" />
      </geometry>
    </collision>
    <inertial>
      <inertia ixx="0.00017" ixy="0.00000" ixz="0.00000" iyy="0.00011" iyz="-0.00000" izz="0.00017" />
      <origin rpy="0.00000 0.00000 0.00000" xyz="0.00000 -0.01855 -0.00000" />
      <mass value="1.00000" />
    </inertial>
    <visual name="right_wheel.003">
      <material name="black" />
      <origin rpy="-1.57080 0.00000 0.00000" xyz="0.00000 -0.01855 -0.00000" />
      <geometry>
        <cylinder radius="0.01500" length="0.03710" />
      </geometry>
    </visual>
  </link>
  <link name="right_wheel.004_link">
    <collision name="right_wheel.004_collision">
      <origin rpy="-1.57080 0.00000 0.00000" xyz="-0.00000 -0.01855 -0.00000" />
      <geometry>
        <cylinder radius="0.01500" length="0.03710" />
      </geometry>
    </collision>
    <inertial>
      <inertia ixx="0.00017" ixy="0.00000" ixz="0.00000" iyy="0.00011" iyz="-0.00000" izz="0.00017" />
      <origin rpy="0.00000 0.00000 0.00000" xyz="0.00000 -0.01855 -0.00000" />
      <mass value="1.00000" />
    </inertial>
    <visual name="right_wheel.004">
      <material name="black" />
      <origin rpy="-1.57080 0.00000 0.00000" xyz="-0.00000 -0.01855 -0.00000" />
      <geometry>
        <cylinder radius="0.01500" length="0.03710" />
      </geometry>
    </visual>
  </link>
  <link name="right_wheel.005_link">
    <collision name="right_wheel.005_collision">
      <origin rpy="-1.57080 0.00000 0.00000" xyz="-0.00000 -0.01855 0.00000" />
      <geometry>
        <cylinder radius="0.01500" length="0.03710" />
      </geometry>
    </collision>
    <inertial>
      <inertia ixx="0.00017" ixy="0.00000" ixz="0.00000" iyy="0.00011" iyz="-0.00000" izz="0.00017" />
      <origin rpy="0.00000 0.00000 0.00000" xyz="0.00000 -0.01855 0.00000" />
      <mass value="1.00000" />
    </inertial>
    <visual name="right_wheel.005">
      <material name="black" />
      <origin rpy="-1.57080 0.00000 0.00000" xyz="-0.00000 -0.01855 0.00000" />
      <geometry>
        <cylinder radius="0.01500" length="0.03710" />
      </geometry>
    </visual>
  </link>
  <link name="right_wheel.006_link">
    <collision name="right_wheel.006_collision">
      <origin rpy="-1.57080 0.00000 0.00000" xyz="0.00000 -0.01855 0.00000" />
      <geometry>
        <cylinder radius="0.01610" length="0.03710" />
      </geometry>
    </collision>
    <inertial>
      <inertia ixx="0.00018" ixy="0.00000" ixz="0.00000" iyy="0.00013" iyz="-0.00000" izz="0.00018" />
      <origin rpy="0.00000 0.00000 0.00000" xyz="0.00000 -0.01855 0.00000" />
      <mass value="1.00000" />
    </inertial>
    <visual name="right_wheel.006">
      <material name="black" />
      <origin rpy="-1.57080 0.00000 0.00000" xyz="0.00000 -0.01855 0.00000" />
      <geometry>
        <cylinder radius="0.01610" length="0.03710" />
      </geometry>
    </visual>
  </link>
  <link name="right_wheel_sprocket_link">
    <collision name="right_wheel_sprocket_collision">
      <origin rpy="-1.57080 0.00000 0.00000" xyz="0.00000 -0.01855 0.00000" />
      <geometry>
        <cylinder radius="0.01610" length="0.03710" />
      </geometry>
    </collision>
    <inertial>
      <inertia ixx="0.00018" ixy="0.00000" ixz="0.00000" iyy="0.00013" iyz="-0.00000" izz="0.00018" />
      <origin rpy="0.00000 0.00000 0.00000" xyz="0.00000 -0.01855 0.00000" />
      <mass value="1.00000" />
    </inertial>
    <visual name="right_wheel_sprocket">
      <material name="black" />
      <origin rpy="-1.57080 0.00000 0.00000" xyz="0.00000 -0.01855 0.00000" />
      <geometry>
        <cylinder radius="0.01610" length="0.03710" />
      </geometry>
    </visual>
  </link>
</robot>